Workbook

Sheet Income Statement
A1: EDITA FOOD INDUSTRIES — Consolidated Income Statement
A4: EGP | B4: Q1 2021 | C4: Q2 2021 | D4: Q3 2021 | E4: FY2021 | F4: Q1 2022 | G4: Q2 2022 | H4: Q3 2022 | I4: FY2022 | J4: Q1 2023 | K4: Q2 2023 | L4: Q3 2023 | M4: FY2023 | N4: Q1 2024 | O4: Q2 2024 | P4: Q3 2024 | Q4: FY2024 | R4: Q1 2025 | S4: Q2 2025 | T4: Q3 2025 | U4: FY2025 | V4: Q1 2026
A5: Revenue | B5: 1166337710 | C5: 1150796202 | D5: 1394672047 | E5: 5251215991 | F5: 1558959966 | G5: 1573182407 | H5: 2015568078 | I5: 7671100869 | J5: 2779712789 | K5: 2858073110 | L5: 3116192430 | M5: 12125997046 | N5: 3927474125 | O5: 4061659438 | P5: 3912039696 | Q5: 16146545699 | R5: 4283378973 | S5: 4963742378 | T5: 5493439566 | U5: 20915072432 | V5: 5770498985
A6: Cost of sales | B6: -768440654 | C6: -812223682 | D6: -983995047 | E6: -3577853519 | F6: -1002344966 | G6: -1054444964 | H6: -1334080177 | I6: -5063343087 | J6: -1900062715 | K6: -1944563261 | L6: -2082111236 | M6: -8200709717 | N6: -2725881009 | O6: -2890469731 | P6: -2691410970 | Q6: -11240232913 | R6: -2930074931 | S6: -3298913868 | T6: -3557144623 | U6: -13723015211 | V6: -3739501996
A7: Gross profit | B7: =SUM(B5:B6) -> 397897056 | C7: =SUM(C5:C6) -> 338572520 | D7: =SUM(D5:D6) -> 410677000 | E7: =SUM(E5:E6) -> 1673362472 | F7: =SUM(F5:F6) -> 556615000 | G7: =SUM(G5:G6) -> 518737443 | H7: =SUM(H5:H6) -> 681487901 | I7: =SUM(I5:I6) -> 2607757782 | ... V7: =SUM(V5:V6) -> 2030996989
A8: Distribution cost | B8: -191997484 | C8: -165341348 | D8: -180819368 | E8: -720231019 | F8: -219534554 | G8: -192858313 | H8: -193725528 | I8: -866522191 | J8: -246921586 | K8: -257345369 | L8: -256784580 | M8: -1131569626 | N8: -370610483 | O8: -383298922 | P8: -388912381 | Q8: -1662351937 | R8: -405359258 | S8: -501234785 | T8: -569975752 | U8: -1998186790 | V8: -628390143
A9: Administrative expenses | B9: -87015114 | C9: -84896674 | D9: -79576132 | E9: -340281645 | F9: -93457025 | G9: -107892361 | H9: -115374078 | I9: -472877272 | J9: -169207945 | K9: -184917558 | L9: -183440195 | M9: -771817875 | N9: -237566629 | O9: -277590802 | P9: -298343651 | Q9: -1086699763 | R9: -365906090 | S9: -331880349 | T9: -358453180 | U9: -1398938050 | V9: -444291046
A10: Provisions (employee/inventory/ECL/other) | B10: 0 | C10: 0 | D10: 0 | E10: 0 | F10: -2475000 | G10: -2475000 | H10: -2475000 | I10: -15750024 | J10: -3500000 | K10: -5933520 | L10: -6282020 | M10: -29281140 | N10: -7864140 | O10: -10533241 | P10: -9913063 | Q10: -37203831 | R10: -11219193 | S10: -17671608 | T10: -16573906 | U10: -115594401 | V10: 21387282
A11: Other income / (losses), net | B11: -6260398 | C11: 28478616 | D11: -1693493 | E11: 19080386 | F11: -4721214 | G11: 8040440 | H11: 2172180 | I11: -22472688 | J11: -15254361 | K11: 34583919 | L11: -11664720 | M11: 12231620 | N11: -11343235 | O11: 11091885 | P11: 29680264 | Q11: 16360427 | R11: -6541682 | S11: 5738761 | T11: 7617288 | U11: 61145635 | V11: 8306938
A12: Finance income | B12: 22291418 | C12: 15467880 | D12: 24742128 | E12: 77084184 | F12: 23618738 | G12: 21479920 | H12: 28299337 | I12: 111754605 | J12: 53442216 | K12: 54755400 | L12: 54777584 | M12: 213587378 | N12: 44882422 | O12: 18990518 | P12: 22766388 | Q12: 168265279 | R12: 77518314 | S12: 122024772 | T12: 170110019 | U12: 575446672 | V12: 265616554
A13: Finance cost | B13: -20206267 | C13: -22235705 | D13: -23056571 | E13: -77409094 | F13: -22241495 | G13: -27416340 | H13: -29204284 | I13: -111551139 | J13: -42611618 | K13: -45162460 | L13: -61346445 | M13: -211931914 | N13: -65031043 | O13: -97564089 | P13: -93660673 | Q13: -402641247 | R13: -134017733 | S13: -142695178 | T13: -167015999 | U13: -602686213 | V13: -155876909
A14: FX gains / (losses) | F14: -5311807 | G14: 2720198 | H14: 3746195 | I14: 34991475 | J14: 47081025 | K14: -4161421 | L14: 3611458 | M14: 44116322 | N14: 36411789 | O14: 17527314 | P14: -7731244 | Q14: 69662331 | R14: 15842614 | S14: 931519 | T14: -33671483 | U14: -9406494 | V14: 45154666
A15: Share of JV / FVTPL / one-offs | B15: 0 | C15: 0 | D15: 0 | E15: 2685432 | F15: -25435336 | G15: 30888746 | H15: 0 | I15: 5453410 | J15: 0 | K15: 0 | L15: 0 | M15: 0 | N15: 0 | O15: 0 | P15: 0 | Q15: 0 | R15: 0 | S15: 0 | T15: 0 | U15: 0 | V15: 0
A16: Profit before income tax | B16: =SUM(B7:B15) -> 114709211 | C16: =SUM(C7:C15) -> 110045289 | D16: =SUM(D7:D15) -> 150273564 | E16: =SUM(E7:E15) -> 634290716 | F16: =SUM(F7:F15) -> 207057307 | G16: =SUM(G7:G15) -> 251224733 | H16: =SUM(H7:H15) -> 374926723 | I16: =SUM(I7:I15) -> 1270783958 | ... V16: =SUM(V7:V15) -> 1142904331
A17: Income tax expense | B17: -34009923 | C17: -27015006 | D17: -37836934 | E17: -162387113 | F17: -58951903 | G17: -55213541 | H17: -88865289 | I17: -311351887 | J17: -127283328 | K17: -123190557 | L17: -148069742 | M17: -544046655 | N17: -154089296 | O17: -136561450 | P17: -117254135 | Q17: -556329772 | R17: -142593186 | S17: -212137839 | T17: -260195045 | U17: -1008535910 | V17: -290850602
A18: Net profit for the period | B18: =SUM(B16:B17) -> 80699288 | C18: =SUM(C16:C17) -> 83030283 | D18: =SUM(D16:D17) -> 112436630 | E18: =SUM(E16:E17) -> 471903603 | F18: =SUM(F16:F17) -> 148105404 | G18: =SUM(G16:G17) -> 196011192 | H18: =SUM(H16:H17) -> 286061434 | I18: =SUM(I16:I17) -> 959432071 | ... V18: =SUM(V16:V17) -> 852053729
A19: Owners of the parent | B19: 81694706 | C19: 82696208 | D19: 112750706 | E19: 471737825 | F19: 148071081 | G19: 196653063 | H19: 286970365 | I19: 964866603 | J19: 374142968 | K19: 385867086 | L19: 430637267 | M19: 1524789018 | N19: 439818756 | O19: 318198469 | P19: 361707936 | Q19: 1442374792 | R19: 384563617 | S19: 593144654 | T19: 715516293 | U19: 2749571345 | V19: 873819839
A20: Non-controlling interest | B20: -995418 | C20: 334075 | D20: -314076 | E20: 165778 | F20: 34323 | G20: -641871 | H20: -908931 | I20: -5434532 | J20: 1251509 | K20: -3728803 | L20: -5754733 | M20: -18213579 | N20: -3436255 | O20: -4947549 | P20: -4447705 | Q20: -27000519 | R20: -3535789 | S20: -5240851 | T20: -7379408 | U20: -54269675 | V20: -21766110
A21: Earnings per share (EGP) | B21: 0.11 | C21: 0.114 | D21: 0.16 | E21: 0.65 | F21: 0.2 | G21: 0.27 | H21: 0.4 | I21: 1.36 | J21: 0.53 | K21: 0.55 | L21: 0.62 | M21: 2.17 | N21: 0.63 | O21: 0.45 | P21: 0.52 | Q21: 2.06 | R21: 0.55 | S21: 0.6 | T21: 0.48 | U21: 2.18 | V21: 0.59
A23: PROFITABILITY MARGINS
A24: Gross margin % | B24: =B7/B5 -> 0.34115081 | C24: =C7/C5 -> 0.29420719 | D24: =D7/D5 -> 0.29446134 | E24: =E7/E5 -> 0.3186619 | F24: =F7/F5 -> 0.35704252 | G24: =G7/G5 -> 0.32973763 | H24: =H7/H5 -> 0.33811207 | I24: =I7/I5 -> 0.3399457 | ... V24: =V7/V5 -> 0.35196211
A25: PBT margin % | B25: =B16/B5 -> 0.098349912 | C25: =C16/C5 -> 0.095625349 | D25: =D16/D5 -> 0.10774832 | E25: =E16/E5 -> 0.1207893 | F25: =F16/F5 -> 0.13281759 | G25: =G16/G5 -> 0.15969206 | H25: =H16/H5 -> 0.18601541 | I25: =I16/I5 -> 0.16565862 | ... V25: =V16/V5 -> 0.19805988
A26: Net margin % | B26: =B18/B5 -> 0.069190327 | C26: =C18/C5 -> 0.072150293 | D26: =D18/D5 -> 0.080618688 | E26: =E18/E5 -> 0.089865586 | F26: =F18/F5 -> 0.095002699 | G26: =G18/G5 -> 0.12459534 | H26: =H18/H5 -> 0.14192596 | I26: =I18/I5 -> 0.12507098 | ... V26: =V18/V5 -> 0.14765685

Sheet Balance Sheet
A1: EDITA FOOD INDUSTRIES — Consolidated Balance Sheet
A4: EGP | B4: Q1 2021 | C4: Q2 2021 | D4: Q3 2021 | E4: FY2021 | F4: Q1 2022 | G4: Q2 2022 | H4: Q3 2022 | I4: FY2022 | J4: Q1 2023 | K4: Q2 2023 | L4: Q3 2023 | M4: FY2023 | N4: Q1 2024 | O4: Q2 2024 | P4: Q3 2024 | Q4: FY2024 | R4: Q1 2025 | S4: Q2 2025 | T4: Q3 2025 | U4: FY2025 | V4: Q1 2026
A5: ASSETS
A6: Property, plant & equipment | B6: 2323470466 | C6: 2346389317 | D6: 2344924764 | E6: 2165626284 | F6: 2160251623 | G6: 2362536619 | H6: 2470518572 | I6: 2542701504 | J6: 2646209707 | K6: 3074547128 | L6: 3099590380 | M6: 3371427161 | N6: 3840585520 | O6: 4180870117 | P6: 4358321026 | Q6: 4459743474 | R6: 4626742780 | S6: 4738654843 | T6: 5067697938 | U6: 5473026194 | V6: 5787706605
A7: Right-of-use assets | B7: 72228726 | C7: 69504007 | D7: 66321750 | E7: 47149933 | F7: 43697475 | G7: 58868257 | H7: 81712986 | I7: 96235414 | J7: 105032432 | K7: 127820002 | L7: 120784435 | M7: 118455576 | N7: 152369074 | O7: 150795329 | P7: 202664941 | Q7: 199536464 | R7: 201047957 | S7: 219227708 | T7: 445138366 | U7: 471665836 | V7: 542965016
A8: Intangible assets & goodwill | B8: 165888068 | C8: 165223557 | D8: 165705675 | E8: 180713178 | F8: 179572144 | G8: 232673969 | H8: 231112173 | I8: 229226565 | J8: 227340955 | K8: 225710973 | L8: 225192408 | M8: 264367647 | N8: 314367055 | O8: 318800466 | P8: 315178047 | Q8: 345553928 | R8: 339003177 | S8: 334353666 | T8: 238258830 | U8: 298916619 | V8: 311497661
A9: Investment in joint venture | E9: 69445134 | F9: 69361875 | T9: 138351801 | U9: 158769416 | V9: 180023178
A10: Deferred tax assets | O10: 51013564 | P10: 59828021 | Q10: 99659439 | R10: 116454966
A11: Inventories | B11: 317039134 | C11: 355518983 | D11: 426042634 | E11: 526494168 | F11: 506530723 | G11: 648994733 | H11: 825856111 | I11: 981499151 | J11: 1314225489 | K11: 1386508882 | L11: 1615431141 | M11: 1866984476 | N11: 2013168512 | O11: 2395457077 | P11: 2935552303 | Q11: 3034025532 | R11: 2248375052 | S11: 2021725974 | T11: 2391304149 | U11: 2315050051 | V11: 2548029569
A12: Trade & other receivables | B12: 201535452 | C12: 161724279 | D12: 215182804 | E12: 218916999 | F12: 244082295 | G12: 360122584 | H12: 352281334 | I12: 545215216 | J12: 523890477 | K12: 618080934 | L12: 618884818 | M12: 780069438 | N12: 1245264923 | O12: 983664728 | P12: 1021485043 | Q12: 846997383 | R12: 631213623 | S12: 196957132 | T12: 223559809 | U12: 243511563 | V12: 328019410
A13: Other debit balances | S13: 585471586 | T13: 750371277 | U13: 947732627 | V13: 1265449382
A14: Due from related parties | S14: 27238719 | T14: 27787612 | U14: 89033817 | V14: 28125296
A15: Financial assets — amortized cost | B15: 512595367 | C15: 527695113 | D15: 690192707 | E15: 769965310 | F15: 846170545 | G15: 682827983 | H15: 753680638 | I15: 894641441 | J15: 1194779566 | K15: 860439291 | L15: 900515962 | M15: 346432739 | N15: 710774116 | P15: 670821833 | Q15: 805867012 | R15: 1470298333 | S15: 2055401482 | T15: 2510350277 | U15: 3445357884 | V15: 4237595554
A16: Financial assets — FVTPL | C16: 71662472 | D16: 75074278 | E16: 76403685 | F16: 66125663 | U16: 578992890 | V16: 192805981
A17: Cash & cash equivalents | B17: 234316430 | C17: 98990078 | D17: 114176127 | E17: 163455483 | F17: 216567822 | G17: 368908371 | H17: 524192529 | I17: 494387411 | J17: 365177423 | K17: 477116838 | L17: 531174606 | M17: 1009902806 | N17: 863036778 | O17: 878674365 | P17: 695037428 | Q17: 518288835 | R17: 1326798901 | S17: 1377082859 | T17: 2013855849 | U17: 716765194 | V17: 1382347681
A18: TOTAL ASSETS | B18: =SUM(B6:B17) -> 3827073643 | C18: =SUM(C6:C17) -> 3796707806 | D18: =SUM(D6:D17) -> 4097620739 | E18: =SUM(E6:E17) -> 4218170174 | F18: =SUM(F6:F17) -> 4332360165 | G18: =SUM(G6:G17) -> 4714932516 | H18: =SUM(H6:H17) -> 5239354343 | I18: =SUM(I6:I17) -> 5783906702 | ... V18: =SUM(V6:V17) -> 16804565333
A19: EQUITY
A20: Share capital | B20: 145072580 | C20: 144611688 | D20: 144611688 | E20: 144611688 | F20: 144611688 | G20: 144611688 | H20: 144611688 | I20: 144611688 | J20: 144611688 | K20: 144611688 | L20: 144611688 | M20: 140002731 | N20: 140002731 | O20: 140002731 | P20: 140002731 | Q20: 140002731 | R20: 140002731 | S20: 280005462 | T20: 280005462 | U20: 280005462 | V20: 280005462
A21: Amounts under capital increase | R21: 140002731
A22: Legal reserve | B22: 78629880 | C22: 78629880 | D22: 78629880 | E22: 78953630 | F22: 78953630 | G22: 78953630 | H22: 78953630 | I22: 78953630 | J22: 79338742 | K22: 72536290 | L22: 72536290 | M22: 72536289 | N22: 72536289 | O22: 72536289 | P22: 72536289 | Q22: 72536289 | R22: 72536289 | S22: 72536289 | T22: 72536289 | U22: 140002729 | V22: 140002729
A23: Cumulative translation reserve | B23: 1719812 | C23: 2866596 | D23: 1615240 | E23: 1190318 | F23: -11128183 | G23: -17759720 | H23: -28555699 | I23: -42273721 | J23: -69820142 | K23: -69622927 | L23: -75158386 | M23: -50615771 | N23: -175998875 | O23: -177822645 | P23: -171560881 | Q23: -208115650 | R23: -195798984 | S23: -171278902 | T23: -148863969 | U23: -143568018 | V23: -272431095
A24: Transactions with NCI | B24: -32132098 | C24: -46229227 | D24: -46229227 | E24: -32132098 | F24: -32132098 | G24: -32132098 | H24: -32132098 | I24: -32132098 | J24: -32132098 | K24: -32132098 | L24: -32132098 | M24: -32132098 | N24: -32132098 | O24: -32132098 | P24: -32132098 | Q24: -32132098 | R24: -32132098 | S24: -32132098 | T24: -32132098 | U24: -32132098 | V24: -32132098
A25: Treasury shares | B25: -22556296 | H25: -58891581 | I25: -160827557 | J25: -160827557 | K25: -266012536 | L25: -266012536 | T25: -192608865 | U25: -192608865 | V25: -192608865
A26: Retained earnings | B26: 1501675740 | C26: 1562276544 | D26: 1675027250 | E26: 1866823044 | F26: 2014894125 | G26: 2011547188 | H26: 2298517553 | I26: 2633270813 | J26: 2607028669 | K26: 2999698207 | L26: 3430335474 | M26: 3199422434 | N26: 3339241190 | O26: 3657439659 | P26: 4019147595 | Q26: 3943619260 | R26: 4218392766 | S26: 4049048455 | T26: 4764564748 | U26: 5672826654 | V26: 6546646493
A27: Non-controlling interests | B27: 34095761 | C27: 16856243 | D27: 21469868 | E27: 590046 | F27: 544955 | G27: 19898273 | H27: 32989334 | I27: 40579768 | J27: 53704746 | K27: 51478618 | L27: 44070453 | M27: 73686956 | N27: 115398273 | O27: 113823117 | P27: 112259979 | Q27: 101270857 | R27: 100993473 | S27: 97795757 | T27: 436782927 | U27: 367793335 | V27: 449951986
A28: TOTAL EQUITY | B28: =SUM(B20:B27) -> 1706505379 | C28: =SUM(C20:C27) -> 1759011724 | D28: =SUM(D20:D27) -> 1875124699 | E28: =SUM(E20:E27) -> 2060036628 | F28: =SUM(F20:F27) -> 2195744117 | G28: =SUM(G20:G27) -> 2205118961 | H28: =SUM(H20:H27) -> 2435492827 | I28: =SUM(I20:I27) -> 2662182523 | ... V28: =SUM(V20:V27) -> 6919434612
A29: LIABILITIES
A30: Borrowings — non-current | B30: 718330248 | C30: 689109657 | D30: 717161179 | E30: 587634700 | F30: 624800696 | G30: 724394978 | H30: 664167702 | I30: 739496389 | J30: 774086738 | K30: 669070263 | L30: 781380051 | M30: 1129283746 | N30: 1548664830 | O30: 1856675621 | P30: 2015303238 | Q30: 2282057064 | R30: 2755995420 | S30: 2523589344 | T30: 3048408172 | U30: 2886725728 | V30: 3057939556
A31: Deferred govt grants — non-current | B31: 8952299 | C31: 8723020 | D31: 9277655 | E31: 9897288 | F31: 9145591 | G31: 9145091 | H31: 8126550 | I31: 16912608 | J31: 18744509 | K31: 18141130 | L31: 16849948 | M31: 17059424 | N31: 22521821 | O31: 22468841 | P31: 22573137 | Q31: 19343101 | S31: 20286587 | T31: 19197654 | U31: 17841111 | V31: 19941613
A32: Employee benefit obligations | B32: 19838638 | C32: 21213305 | D32: 22706604 | E32: 24103494 | F32: 25603494 | G32: 26959775 | H32: 27737850 | I32: 33396656 | J32: 32407420 | K32: 34573630 | L32: 36513850 | M32: 55143601 | N32: 61140931 | O32: 65789982 | P32: 71581227 | Q32: 75262582 | R32: 81333759 | S32: 86916760 | T32: 92696288 | U32: 114366146 | V32: 120619795
A33: Deferred tax liabilities | B33: 178675864 | C33: 184397007 | D33: 194177722 | E33: 204828607 | F33: 203035166 | G33: 193048743 | H33: 206560974 | I33: 194682549 | J33: 187704647 | K33: 206715826 | L33: 204711225 | M33: 240132883 | N33: 216359658 | O33: 260959242 | P33: 283793717 | Q33: 402132045 | R33: 414778644 | S33: 301901467 | T33: 317354796 | U33: 369666761 | V33: 357438147
A34: Lease liabilities — non-current | B34: 77153124 | C34: 75448447 | D34: 72847284 | E34: 51734242 | F34: 49815740 | G34: 67398027 | H34: 87249411 | I34: 102209569 | J34: 113931000 | K34: 136156743 | L34: 130856324 | M34: 130944266 | N34: 171945690 | O34: 173823587 | P34: 229315720 | Q34: 229107964 | R34: 236616917 | S34: 260712943 | T34: 486334737 | U34: 512767017 | V34: 596067812
A35: Provisions | B35: 35221812 | C35: 35862197 | D35: 37300108 | E35: 33978251 | F35: 34820100 | G35: 36017119 | H35: 36793356 | I35: 72714382 | J35: 79577633 | K35: 91728516 | L35: 93173519 | M35: 105601704 | N35: 111153057 | O35: 119047434 | P35: 128871024 | Q35: 99601868 | R35: 103293905 | S35: 98985499 | T35: 93365775 | U35: 111646561 | V35: 63160752
A36: Bank overdraft | B36: 28118109 | C36: 201889618 | D36: 300745343 | E36: 404566831 | F36: 213028371 | G36: 430365827 | H36: 373050099 | I36: 501662588 | J36: 349946625 | K36: 964918669 | L36: 696049094 | M36: 596722472 | N36: 866703114 | O36: 388410854 | P36: 839070484 | Q36: 808368965 | R36: 452465022 | S36: 702879167 | T36: 1024709593 | U36: 771424343 | V36: 902032996
A37: Trade & other payables | B37: 803004198 | C37: 622687793 | D37: 660485107 | E37: 605949105 | F37: 666027733 | G37: 684257684 | H37: 911521896 | I37: 1006229685 | J37: 1552105314 | K37: 1175705669 | L37: 1140929731 | M37: 1383888532 | N37: 1858305563 | O37: 1714528601 | P37: 1991682634 | Q37: 1747657368 | R37: 1631883708 | S37: 1282750762 | T37: 1396790456 | U37: 1582315367 | V37: 1741629704
A38: Other credit balances | S38: 1160105256 | T38: 1143843597 | U38: 932749514 | V38: 1243414604
A39: Current portion of borrowings | B39: 189201771 | C39: 187687114 | D39: 198384430 | E39: 197005385 | F39: 211734212 | G39: 222509173 | H39: 299317615 | I39: 244539007 | J39: 317882127 | K39: 354061456 | L39: 361464563 | M39: 297757493 | N39: 272760115 | O39: 340084334 | P39: 257724321 | Q39: 372899145 | R39: 454055445 | S39: 591468538 | T39: 768292584 | U39: 813869286 | V39: 999364058
A40: Current portion of govt grants | S40: 3226290 | T40: 3023074 | U40: 2587049 | V40: 2318516
A41: Current income tax liabilities | B41: 55203085 | C41: 3565908 | D41: 1669593 | E41: 30584092 | F41: 89867694 | G41: 106612205 | H41: 176999679 | I41: 197610283 | J41: 315495614 | K41: 204875393 | L41: 318283876 | M41: 387712322 | N41: 540089660 | O41: 233515937 | P41: 269764027 | Q41: 248382615 | R41: 376289070 | S41: 218276029 | T41: 219653272 | U41: 514276098 | V41: 764162461
A42: Lease liabilities — current | B42: 6869116 | C42: 7112016 | D42: 7741015 | E42: 7851551 | F42: 8737251 | G42: 9104933 | H42: 12336384 | I42: 12270463 | J42: 12870374 | K42: 13719511 | L42: 13110684 | M42: 10492859 | N42: 10874029 | O42: 10124160 | P42: 8955498 | Q42: 7677961 | R42: 9225991 | S42: 9040364 | T42: 12721416 | U42: 16267911 | V42: 17040707
...

Sheet Financial Ratios
A1: EDITA FOOD INDUSTRIES — Financial Ratio Analysis
A4: EGP | B4: Q1 2021 | C4: Q2 2021 | D4: Q3 2021 | E4: FY2021 | F4: Q1 2022 | G4: Q2 2022 | H4: Q3 2022 | I4: FY2022 | J4: Q1 2023 | K4: Q2 2023 | L4: Q3 2023 | M4: FY2023 | N4: Q1 2024 | O4: Q2 2024 | P4: Q3 2024 | Q4: FY2024 | R4: Q1 2025 | S4: Q2 2025 | T4: Q3 2025 | U4: FY2025 | V4: Q1 2026
A5: Annualisation factor (×) | B5: 4 | C5: 4 | D5: 4 | E5: 1 | F5: 4 | G5: 4 | H5: 4 | I5: 1 | J5: 4 | K5: 4 | L5: 4 | M5: 1 | N5: 4 | O5: 4 | P5: 4 | Q5: 1 | R5: 4 | S5: 4 | T5: 4 | U5: 1 | V5: 4
A6: LIQUIDITY
A7: Current ratio (x) | B7: =SUM('Balance Sheet'!B11:B17)/SUM('Balance Sheet'!B35:B42) -> 1.1323066 | C7: =SUM('Balance Sheet'!C11:C17)/SUM('Balance Sheet'!C35:C42) -> 1.1480786 | D7: =SUM('Balance Sheet'!D11:D17)/SUM('Balance Sheet'!D35:D42) -> 1.2605789 | E7: =SUM('Balance Sheet'!E11:E17)/SUM('Balance Sheet'!E35:E42) -> 1.3713473 | F7: =SUM('Balance Sheet'!F11:F17)/SUM('Balance Sheet'!F35:F42) -> 1.5352503 | G7: =SUM('Balance Sheet'!G11:G17)/SUM('Balance Sheet'!G35:G42) -> 1.3841759 | H7: =SUM('Balance Sheet'!H11:H17)/SUM('Balance Sheet'!H35:H42) -> 1.3568977 | I7: =SUM('Balance Sheet'!I11:I17)/SUM('Balance Sheet'!I35:I42) -> 1.4327791 | ... V7: =SUM('Balance Sheet'!V11:V17)/SUM('Balance Sheet'!V35:V42) -> 1.7411752
A8: Quick ratio (x) | B8: =SUM('Balance Sheet'!B12:B17)/SUM('Balance Sheet'!B35:B42) -> 0.84863269 | C8: =SUM('Balance Sheet'!C12:C17)/SUM('Balance Sheet'!C35:C42) -> 0.81230465 | D8: =SUM('Balance Sheet'!D12:D17)/SUM('Balance Sheet'!D35:D42) -> 0.90740503 | E8: =SUM('Balance Sheet'!E12:E17)/SUM('Balance Sheet'!E35:E42) -> 0.96000287 | F8: =SUM('Balance Sheet'!F12:F17)/SUM('Balance Sheet'!F35:F42) -> 1.1214908 | G8: =SUM('Balance Sheet'!G12:G17)/SUM('Balance Sheet'!G35:G42) -> 0.94827744 | H8: =SUM('Balance Sheet'!H12:H17)/SUM('Balance Sheet'!H35:H42) -> 0.90062838 | I8: =SUM('Balance Sheet'!I12:I17)/SUM('Balance Sheet'!I35:I42) -> 0.95047615 | ... V8: =SUM('Balance Sheet'!V12:V17)/SUM('Balance Sheet'!V35:V42) -> 1.2967352
A9: Cash ratio (x) | B9: ='Balance Sheet'!B17/SUM('Balance Sheet'!B35:B42) -> 0.20965698 | C9: ='Balance Sheet'!C17/SUM('Balance Sheet'!C35:C42) -> 0.093492297 | D9: ='Balance Sheet'!D17/SUM('Balance Sheet'!D35:D42) -> 0.094647852 | E9: ='Balance Sheet'!E17/SUM('Balance Sheet'!E35:E42) -> 0.12770606 | F9: ='Balance Sheet'!F17/SUM('Balance Sheet'!F35:F42) -> 0.17690337 | G9: ='Balance Sheet'!G17/SUM('Balance Sheet'!G35:G42) -> 0.24777793 | H9: ='Balance Sheet'!H17/SUM('Balance Sheet'!H35:H42) -> 0.28960609 | I9: ='Balance Sheet'!I17/SUM('Balance Sheet'!I35:I42) -> 0.24293906 | ... V9: ='Balance Sheet'!V17/SUM('Balance Sheet'!V35:V42) -> 0.24111597
A10: Net working capital (EGP) | B10: =SUM('Balance Sheet'!B11:B17)-SUM('Balance Sheet'!B35:B42) -> 147868292 | C10: =SUM('Balance Sheet'!C11:C17)-SUM('Balance Sheet'!C35:C42) -> 156786279 | D10: =SUM('Balance Sheet'!D11:D17)-SUM('Balance Sheet'!D35:D42) -> 314342954 | E10: =SUM('Balance Sheet'!E11:E17)-SUM('Balance Sheet'!E35:E42) -> 475300430 | F10: =SUM('Balance Sheet'!F11:F17)-SUM('Balance Sheet'!F35:F42) -> 655261687 | G10: =SUM('Balance Sheet'!G11:G17)-SUM('Balance Sheet'!G35:G42) -> 571986730 | H10: =SUM('Balance Sheet'!H11:H17)-SUM('Balance Sheet'!H35:H42) -> 645991583 | I10: =SUM('Balance Sheet'!I11:I17)-SUM('Balance Sheet'!I35:I42) -> 880716811 | ... V10: =SUM('Balance Sheet'!V11:V17)-SUM('Balance Sheet'!V35:V42) -> 4249249075
A11: PROFITABILITY
A12: Gross margin % | B12: ='Income Statement'!B7/'Income Statement'!B5 -> 0.34115081 | C12: ='Income Statement'!C7/'Income Statement'!C5 -> 0.29420719 | D12: ='Income Statement'!D7/'Income Statement'!D5 -> 0.29446134 | E12: ='Income Statement'!E7/'Income Statement'!E5 -> 0.3186619 | F12: ='Income Statement'!F7/'Income Statement'!F5 -> 0.35704252 | G12: ='Income Statement'!G7/'Income Statement'!G5 -> 0.32973763 | H12: ='Income Statement'!H7/'Income Statement'!H5 -> 0.33811207 | I12: ='Income Statement'!I7/'Income Statement'!I5 -> 0.3399457 | ... V12: ='Income Statement'!V7/'Income Statement'!V5 -> 0.35196211
A13: Operating margin % (PBT-based) | B13: ='Income Statement'!B16/'Income Statement'!B5 -> 0.098349912 | C13: ='Income Statement'!C16/'Income Statement'!C5 -> 0.095625349 | D13: ='Income Statement'!D16/'Income Statement'!D5 -> 0.10774832 | E13: ='Income Statement'!E16/'Income Statement'!E5 -> 0.1207893 | F13: ='Income Statement'!F16/'Income Statement'!F5 -> 0.13281759 | G13: ='Income Statement'!G16/'Income Statement'!G5 -> 0.15969206 | H13: ='Income Statement'!H16/'Income Statement'!H5 -> 0.18601541 | I13: ='Income Statement'!I16/'Income Statement'!I5 -> 0.16565862 | ... V13: ='Income Statement'!V16/'Income Statement'!V5 -> 0.19805988
A14: Net margin % | B14: ='Income Statement'!B18/'Income Statement'!B5 -> 0.069190327 | C14: ='Income Statement'!C18/'Income Statement'!C5 -> 0.072150293 | D14: ='Income Statement'!D18/'Income Statement'!D5 -> 0.080618688 | E14: ='Income Statement'!E18/'Income Statement'!E5 -> 0.089865586 | F14: ='Income Statement'!F18/'Income Statement'!F5 -> 0.095002699 | G14: ='Income Statement'!G18/'Income Statement'!G5 -> 0.12459534 | H14: ='Income Statement'!H18/'Income Statement'!H5 -> 0.14192596 | I14: ='Income Statement'!I18/'Income Statement'!I5 -> 0.12507098 | ... V14: ='Income Statement'!V18/'Income Statement'!V5 -> 0.14765685
A15: Return on assets (ROA) % — annualised | B15: ='Income Statement'!B18*B$5/'Balance Sheet'!B18 -> 0.084345686 | C15: ='Income Statement'!C18*C$5/'Balance Sheet'!C18 -> 0.087476084 | D15: ='Income Statement'!D18*D$5/'Balance Sheet'!D18 -> 0.10975797 | E15: ='Income Statement'!E18*E$5/'Balance Sheet'!E18 -> 0.11187401 | F15: ='Income Statement'!F18*F$5/'Balance Sheet'!F18 -> 0.13674339 | G15: ='Income Statement'!G18*G$5/'Balance Sheet'!G18 -> 0.16628971 | H15: ='Income Statement'!H18*H$5/'Balance Sheet'!H18 -> 0.21839442 | I15: ='Income Statement'!I18*I$5/'Balance Sheet'!I18 -> 0.16587959 | ... V15: ='Income Statement'!V18*V$5/'Balance Sheet'!V18 -> 0.20281482
A16: Return on equity (ROE) % — annualised | B16: ='Income Statement'!B18*B$5/'Balance Sheet'!B28 -> 0.18915683 | C16: ='Income Statement'!C18*C$5/'Balance Sheet'!C28 -> 0.18881121 | D16: ='Income Statement'!D18*D$5/'Balance Sheet'!D28 -> 0.23984886 | E16: ='Income Statement'!E18*E$5/'Balance Sheet'!E28 -> 0.22907535 | F16: ='Income Statement'!F18*F$5/'Balance Sheet'!F28 -> 0.26980449 | G16: ='Income Statement'!G18*G$5/'Balance Sheet'!G28 -> 0.35555668 | H16: ='Income Statement'!H18*H$5/'Balance Sheet'!H28 -> 0.46982102 | I16: ='Income Statement'!I18*I$5/'Balance Sheet'!I28 -> 0.36039305 | ... V16: ='Income Statement'!V18*V$5/'Balance Sheet'!V28 -> 0.49255685
A17: LEVERAGE & SOLVENCY
A18: Total debt (EGP) | B18: ='Balance Sheet'!B30+'Balance Sheet'!B34+'Balance Sheet'!B36+'Balance Sheet'!B39+'Balance Sheet'!B42 -> 1019672368 | C18: ='Balance Sheet'!C30+'Balance Sheet'!C34+'Balance Sheet'!C36+'Balance Sheet'!C39+'Balance Sheet'!C42 -> 1161246852 | D18: ='Balance Sheet'!D30+'Balance Sheet'!D34+'Balance Sheet'!D36+'Balance Sheet'!D39+'Balance Sheet'!D42 -> 1296879251 | E18: ='Balance Sheet'!E30+'Balance Sheet'!E34+'Balance Sheet'!E36+'Balance Sheet'!E39+'Balance Sheet'!E42 -> 1248792709 | F18: ='Balance Sheet'!F30+'Balance Sheet'!F34+'Balance Sheet'!F36+'Balance Sheet'!F39+'Balance Sheet'!F42 -> 1108116270 | G18: ='Balance Sheet'!G30+'Balance Sheet'!G34+'Balance Sheet'!G36+'Balance Sheet'!G39+'Balance Sheet'!G42 -> 1453772938 | H18: ='Balance Sheet'!H30+'Balance Sheet'!H34+'Balance Sheet'!H36+'Balance Sheet'!H39+'Balance Sheet'!H42 -> 1436121211 | I18: ='Balance Sheet'!I30+'Balance Sheet'!I34+'Balance Sheet'!I36+'Balance Sheet'!I39+'Balance Sheet'!I42 -> 1600178016 | ... V18: ='Balance Sheet'!V30+'Balance Sheet'!V34+'Balance Sheet'!V36+'Balance Sheet'!V39+'Balance Sheet'!V42 -> 5572445129
A19: Net debt (EGP) | B19: =B18-'Balance Sheet'!B17 -> 785355938 | C19: =C18-'Balance Sheet'!C17 -> 1062256774 | D19: =D18-'Balance Sheet'!D17 -> 1182703124 | E19: =E18-'Balance Sheet'!E17 -> 1085337226 | F19: =F18-'Balance Sheet'!F17 -> 891548448 | G19: =G18-'Balance Sheet'!G17 -> 1084864567 | H19: =H18-'Balance Sheet'!H17 -> 911928682 | I19: =I18-'Balance Sheet'!I17 -> 1105790605 | ... V19: =V18-'Balance Sheet'!V17 -> 4190097448
A20: Debt / Equity (x) | B20: =B18/'Balance Sheet'!B28 -> 0.59752075 | C20: =C18/'Balance Sheet'!C28 -> 0.66017005 | D20: =D18/'Balance Sheet'!D28 -> 0.69162294 | E20: =E18/'Balance Sheet'!E28 -> 0.60619927 | F20: =F18/'Balance Sheet'!F28 -> 0.50466549 | G20: =G18/'Balance Sheet'!G28 -> 0.65927189 | H20: =H18/'Balance Sheet'!H28 -> 0.58966349 | I20: =I18/'Balance Sheet'!I28 -> 0.6010775 | ... V20: =V18/'Balance Sheet'!V28 -> 0.80533244
A21: Net debt / Equity (x) | B21: =B19/'Balance Sheet'!B28 -> 0.46021299 | C21: =C19/'Balance Sheet'!C28 -> 0.60389408 | D21: =D19/'Balance Sheet'!D28 -> 0.63073305 | E21: =E19/'Balance Sheet'!E28 -> 0.52685336 | F21: =F19/'Balance Sheet'!F28 -> 0.40603477 | G21: =G19/'Balance Sheet'!G28 -> 0.49197553 | H21: =H19/'Balance Sheet'!H28 -> 0.37443292 | I21: =I19/'Balance Sheet'!I28 -> 0.41536994 | ... V21: =V19/'Balance Sheet'!V28 -> 0.60555489
A22: Equity / Assets % | B22: ='Balance Sheet'!B28/'Balance Sheet'!B18 -> 0.44590346 | C22: ='Balance Sheet'!C28/'Balance Sheet'!C18 -> 0.46329921 | D22: ='Balance Sheet'!D28/'Balance Sheet'!D18 -> 0.45761304 | E22: ='Balance Sheet'!E28/'Balance Sheet'!E18 -> 0.4883721 | F22: ='Balance Sheet'!F28/'Balance Sheet'!F18 -> 0.506824 | G22: ='Balance Sheet'!G28/'Balance Sheet'!G18 -> 0.46768834 | H22: ='Balance Sheet'!H28/'Balance Sheet'!H18 -> 0.46484598 | I22: ='Balance Sheet'!I28/'Balance Sheet'!I18 -> 0.46027411 | ... V22: ='Balance Sheet'!V28/'Balance Sheet'!V18 -> 0.41175921
A23: Interest coverage (x) | B23: =('Income Statement'!B16-'Income Statement'!B13)/(-'Income Statement'!B13) -> 6.6769126 | C23: =('Income Statement'!C16-'Income Statement'!C13)/(-'Income Statement'!C13) -> 5.9490353 | D23: =('Income Statement'!D16-'Income Statement'!D13)/(-'Income Statement'!D13) -> 7.5176025 | E23: =('Income Statement'!E16-'Income Statement'!E13)/(-'Income Statement'!E13) -> 9.1940077 | F23: =('Income Statement'!F16-'Income Statement'!F13)/(-'Income Statement'!F13) -> 10.309505 | G23: =('Income Statement'!G16-'Income Statement'!G13)/(-'Income Statement'!G13) -> 10.163321 | H23: =('Income Statement'!H16-'Income Statement'!H13)/(-'Income Statement'!H13) -> 13.838073 | I23: =('Income Statement'!I16-'Income Statement'!I13)/(-'Income Statement'!I13) -> 12.391941 | ... V23: =('Income Statement'!V16-'Income Statement'!V13)/(-'Income Statement'!V13) -> 8.3320952
A24: EFFICIENCY (flows annualised ×factor)
A25: Asset turnover (x) | B25: ='Income Statement'!B5*B$5/'Balance Sheet'!B18 -> 1.2190387 | C25: ='Income Statement'!C5*C$5/'Balance Sheet'!C18 -> 1.2124148 | D25: ='Income Statement'!D5*D$5/'Balance Sheet'!D18 -> 1.3614457 | E25: ='Income Statement'!E5*E$5/'Balance Sheet'!E18 -> 1.2449038 | F25: ='Income Statement'!F5*F$5/'Balance Sheet'!F18 -> 1.4393632 | G25: ='Income Statement'!G5*G$5/'Balance Sheet'!G18 -> 1.3346383 | H25: ='Income Statement'!H5*H$5/'Balance Sheet'!H18 -> 1.5387912 | I25: ='Income Statement'!I5*I$5/'Balance Sheet'!I18 -> 1.3262836 | ... V25: ='Income Statement'!V5*V$5/'Balance Sheet'!V18 -> 1.3735551
A26: Avg.Inventory (EGP) | B26: ='Balance Sheet'!B11 -> 317039134 | C26: =AVERAGE('Balance Sheet'!B11:C11) -> 3.3627906e+08 | D26: =AVERAGE('Balance Sheet'!C11:D11) -> 3.9078081e+08 | E26: =AVERAGE('Balance Sheet'!D11:E11) -> 476268401 | F26: =AVERAGE('Balance Sheet'!E11:F11) -> 5.1651245e+08 | G26: =AVERAGE('Balance Sheet'!F11:G11) -> 577762728 | H26: =AVERAGE('Balance Sheet'!G11:H11) -> 737425422 | I26: =AVERAGE('Balance Sheet'!H11:I11) -> 903677631 | J26: =AVERAGE('Balance Sheet'!I11:J11) -> 1147862320 | ... V26: =AVERAGE('Balance Sheet'!U11:V11) -> 2431539810
A27: Inventory turnover (x) | B27: =(-'Income Statement'!B6)*B$5/B26 -> 9.6952152 | C27: =(-'Income Statement'!C6)*C$5/C26 -> 9.6613055 | D27: =(-'Income Statement'!D6)*D$5/D26 -> 10.072092 | E27: =(-'Income Statement'!E6)*E$5/E26 -> 7.5122631 | F27: =(-'Income Statement'!F6)*F$5/F26 -> 7.7624071 | G27: =(-'Income Statement'!G6)*G$5/G26 -> 7.3001938 | H27: =(-'Income Statement'!H6)*H$5/H26 -> 7.2364209 | I27: =(-'Income Statement'!I6)*I$5/I26 -> 5.6030413 | ... V27: =(-'Income Statement'!V6)*V$5/V26 -> 6.1516607
A28: Days inventory (DIO) | B28: =365/B27 -> 37.647437 | C28: =365/C27 -> 37.779573 | D28: =365/D27 -> 36.238748 | E28: =365/E27 -> 48.587223 | F28: =365/F27 -> 47.021497 | G28: =365/G27 -> 49.998673 | H28: =365/H27 -> 50.4393 | I28: =365/I27 -> 65.143193 | ... V28: =365/V27 -> 59.333571
A29: Avg.Receivables (EGP) | B29: ='Balance Sheet'!B12 -> 201535452 | C29: =AVERAGE('Balance Sheet'!B12:C12) -> 1.8162987e+08 | D29: =AVERAGE('Balance Sheet'!C12:D12) -> 1.8845354e+08 | E29: =AVERAGE('Balance Sheet'!D12:E12) -> 2.170499e+08 | F29: =AVERAGE('Balance Sheet'!E12:F12) -> 231499647 | G29: =AVERAGE('Balance Sheet'!F12:G12) -> 3.0210244e+08 | H29: =AVERAGE('Balance Sheet'!G12:H12) -> 356201959 | I29: =AVERAGE('Balance Sheet'!H12:I12) -> 448748275 | J29: =AVERAGE('Balance Sheet'!I12:J12) -> 5.3455285e+08 | ... V29: =AVERAGE('Balance Sheet'!U12:V12) -> 2.8576549e+08
A30: Receivables turnover (x) | B30: ='Income Statement'!B5*B$5/B29 -> 23.149033 | C30: ='Income Statement'!C5*C$5/C29 -> 25.343766 | D30: ='Income Statement'!D5*D$5/D29 -> 29.602459 | E30: ='Income Statement'!E5*E$5/E29 -> 24.193588 | F30: ='Income Statement'!F5*F$5/F29 -> 26.936714 | G30: ='Income Statement'!G5*G$5/G29 -> 20.829788 | H30: ='Income Statement'!H5*H$5/H29 -> 22.633992 | I30: ='Income Statement'!I5*I$5/I29 -> 17.094441 | ... V30: ='Income Statement'!V5*V$5/V29 -> 80.772511
A31: Days sales outstanding (DSO) | B31: =365/B30 -> 15.767397 | C31: =365/C30 -> 14.401964 | D31: =365/D30 -> 12.330057 | E31: =365/E30 -> 15.086642 | F31: =365/F30 -> 13.550279 | G31: =365/G30 -> 17.522982 | H31: =365/H30 -> 16.126188 | I31: =365/I30 -> 21.351971 | ... V31: =365/V30 -> 4.5188641
A32: Avg.Payables (EGP) | B32: ='Balance Sheet'!B37 -> 803004198 | C32: =AVERAGE('Balance Sheet'!B37:C37) -> 7.12846e+08 | D32: =AVERAGE('Balance Sheet'!C37:D37) -> 641586450 | E32: =AVERAGE('Balance Sheet'!D37:E37) -> 633217106 | F32: =AVERAGE('Balance Sheet'!E37:F37) -> 635988419 | G32: =AVERAGE('Balance Sheet'!F37:G37) -> 6.7514271e+08 | H32: =AVERAGE('Balance Sheet'!G37:H37) -> 797889790 | I32: =AVERAGE('Balance Sheet'!H37:I37) -> 9.5887579e+08 | J32: =AVERAGE('Balance Sheet'!I37:J37) -> 1.2791675e+09 | ... V32: =AVERAGE('Balance Sheet'!U37:V37) -> 1.6619725e+09
A33: Payables Turnover | B33: =-'Income Statement'!B6*B$5/B32 -> 3.8278288 | C33: =-'Income Statement'!C6*C$5/C32 -> 4.557639 | D33: =-'Income Statement'!D6*D$5/D32 -> 6.134762 | E33: =-'Income Statement'!E6*E$5/E32 -> 5.6502793 | F33: =-'Income Statement'!F6*F$5/F32 -> 6.3041712 | G33: =-'Income Statement'!G6*G$5/G32 -> 6.247242 | H33: =-'Income Statement'!H6*H$5/H32 -> 6.6880424 | I33: =-'Income Statement'!I6*I$5/I32 -> 5.2804995 | ... V33: =-'Income Statement'!V6*V$5/V32 -> 9.0001535
A34: Days Payable Outstanding (DPO) | B34: =365/B33 -> 95.354316 | C34: =365/C33 -> 80.085324 | D34: =365/D33 -> 59.49701 | E34: =365/E33 -> 64.598576 | F34: =365/F33 -> 57.898174 | G34: =365/G33 -> 58.425783 | H34: =365/H33 -> 54.575013 | I34: =365/I33 -> 69.122249 | ... V34: =365/V33 -> 40.554864
A35: Cash Conversion Cycle (CCC) | B35: =(B$28+B$31)-B$34 -> -41.939482 | C35: =(C$28+C$31)-C$34 -> -27.903787 | D35: =(D$28+D$31)-D$34 -> -10.928205 | E35: =(E$28+E$31)-E$34 -> -0.92471178 | F35: =(F$28+F$31)-F$34 -> 2.673602 | G35: =(G$28+G$31)-G$34 -> 9.0958728 | H35: =(H$28+H$31)-H$34 -> 11.990474 | I35: =(I$28+I$31)-I$34 -> 17.372914 | ... V35: =(V$28+V$31)-V$34 -> 23.297571
A36: PER-SHARE & GROWTH
A37: EPS (EGP) | B37: ='Income Statement'!B21 -> 0.11 | C37: ='Income Statement'!C21 -> 0.114 | D37: ='Income Statement'!D21 -> 0.16 | E37: ='Income Statement'!E21 -> 0.65 | F37: ='Income Statement'!F21 -> 0.2 | G37: ='Income Statement'!G21 -> 0.27 | H37: ='Income Statement'!H21 -> 0.4 | I37: ='Income Statement'!I21 -> 1.36 | ... V37: ='Income Statement'!V21 -> 0.59
A38: Revenue growth YoY % | F38: ='Income Statement'!F5/'Income Statement'!B5-1 -> 0.33662828 | G38: ='Income Statement'!G5/'Income Statement'!C5-1 -> 0.36703823 | H38: ='Income Statement'!H5/'Income Statement'!D5-1 -> 0.44519142 | I38: ='Income Statement'!I5/'Income Statement'!E5-1 -> 0.46082372 | J38: ='Income Statement'!J5/'Income Statement'!F5-1 -> 0.78305592 | K38: ='Income Statement'!K5/'Income Statement'!G5-1 -> 0.81674617 | L38: ='Income Statement'!L5/'Income Statement'!H5-1 -> 0.54606161 | M38: ='Income Statement'!M5/'Income Statement'!I5-1 -> 0.58073753 | ... V38: ='Income Statement'!V5/'Income Statement'!R5-1 -> 0.34718385
A39: Net profit growth YoY % | F39: ='Income Statement'!F18/'Income Statement'!B18-1 -> 0.83527523 | G39: ='Income Statement'!G18/'Income Statement'!C18-1 -> 1.3607193 | H39: ='Income Statement'!H18/'Income Statement'!D18-1 -> 1.5442014 | I39: ='Income Statement'!I18/'Income Statement'!E18-1 -> 1.0331103 | J39: ='Income Statement'!J18/'Income Statement'!F18-1 -> 1.534644 | K39: ='Income Statement'!K18/'Income Statement'!G18-1 -> 0.94957379 | L39: ='Income Statement'!L18/'Income Statement'!H18-1 -> 0.48528422 | M39: ='Income Statement'!M18/'Income Statement'!I18-1 -> 0.57027838 | ... V39: ='Income Statement'!V18/'Income Statement'!R18-1 -> 1.2361982
A40: MARKET VALUATION
A41: Share price (EGP) — current | B41: 29.14
A42: P/S (x) — current price × shares ÷ annualised revenue | B42: =$B$41*'Income Statement'!B19/('Income Statement'!B5*B$5*'Income Statement'!B21) -> 4.6388088 | C42: =$B$41*'Income Statement'!C19/('Income Statement'!C5*C$5*'Income Statement'!C21) -> 4.5921057 | D42: =$B$41*'Income Statement'!D19/('Income Statement'!D5*D$5*'Income Statement'!D21) -> 3.6809231 | E42: =$B$41*'Income Statement'!E19/('Income Statement'!E5*E$5*'Income Statement'!E21) -> 4.0273281 | F42: =$B$41*'Income Statement'!F19/('Income Statement'!F5*F$5*'Income Statement'!F21) -> 3.4596713 | G42: =$B$41*'Income Statement'!G19/('Income Statement'!G5*G$5*'Income Statement'!G21) -> 3.3727754 | H42: =$B$41*'Income Statement'!H19/('Income Statement'!H5*H$5*'Income Statement'!H21) -> 2.5930396 | I42: =$B$41*'Income Statement'!I19/('Income Statement'!I5*I$5*'Income Statement'!I21) -> 2.695009 | ... V42: =$B$41*'Income Statement'!V19/('Income Statement'!V5*V$5*'Income Statement'!V21) -> 1.8697609

Sheet Cash Flow
A1: EDITA FOOD INDUSTRIES — Consolidated Cash Flows
A4: EGP | B4: FY2021 | C4: FY2022 | D4: FY2023 | E4: FY2024 | F4: FY2025 | G4: Q1 2026
A5: Reporting basis | B5: FY | C5: FY | D5: FY | E5: FY | F5: FY | G5: 3M
A6: OPERATING ACTIVITIES
A7: Profit before income tax | B7: 634290716 | C7: 1270783958 | D7: 2050622094 | E7: 1971704045 | F7: 3703837580
A8: Depreciation — PP&E | B8: 339398313 | D8: 250518978 | E8: 339762089 | F8: 429500144
A9: Depreciation — right-of-use | B9: 23078685 | D9: 24706566 | E9: 22053035 | F9: 35806909
A10: Amortization — intangibles | B10: 11060520 | D10: 7553866 | E10: 11060520 | F10: 12669115
A11: Interest expense | B11: 77409094 | D11: 195775875 | E11: 376398830 | F11: 554787380
A12: Interest income | B12: -77084184 | D12: -213587378 | E12: -168265279 | F12: -556045830
A13: Net cash from operating activities | B13: 311854466 | C13: 861536860 | D13: 1049280113 | E13: 854487748 | F13: 4311415865 | G13: 882208742
A14: INVESTING ACTIVITIES
A15: Capex — PP&E | B15: -146131739 | C15: -296181496 | D15: -572147343 | E15: -1238601054 | F15: -1020200150
A16: Purchase of intangibles | B16: -15495981 | D16: -2326936 | E16: -228000 | F16: -61564140
A17: Proceeds — PP&E sale | B17: 20083916 | D17: 6035664 | E17: 6096820 | F17: 33352073
A18: Interest received | B18: 60911310 | D18: 215911491 | E18: 137960554 | F18: 438015075
A19: Treasury bills purchased | B19: -1137766286 | C19: -1147508720 | D19: -4664845933 | E19: -1955683983 | F19: -8476385049
A20: Treasury bills sold | B20: 885252165 | C20: 1239545316 | D20: 5207775393 | E20: 1518125049 | F20: 5909043739
A21: Net cash from investing activities | B21: -445863521 | C21: -325171347 | D21: -68294071 | E21: -1532330614 | F21: -4139007449 | G21: -367906335
A22: FINANCING ACTIVITIES
A23: Dividends paid | B23: -156145803 | C23: -139463576 | D23: -699700000 | E23: -700000000 | F23: -800100000
A24: Treasury shares purchased | B24: 0 | D24: -105184979 | E24: 0 | F24: -192608865
A25: Borrowings — proceeds | B25: 159408661 | D25: 1166800225 | E25: 802325677 | F25: 1565170723
A26: Borrowings — repayment | B26: -226159644 | D26: -936957728 | E26: -193737275 | F26: -450007937
A27: Net cash from financing activities | B27: -241733558 | C27: -305369948 | D27: -581967136 | E27: -130568961 | F27: 63008118 | G27: 20671427
A28: NET MOVEMENT
A29: Net change in cash | B29: -375742613 | C29: 230995565 | D29: 399018906 | E29: -808411827 | F29: 235416534 | G29: 534973834
A30: Cash at beginning of period | B30: 134631265 | C30: -241111348 | D30: -7275177 | E30: 413180334 | F30: -290075683 | G30: -54659149
A31: FX effect on cash | B31: 0 | C31: 2840606 | D31: 21436605 | E31: 105151363 | F31: 0 | G31: 0
A32: Cash at end of period | B32: -241111348 | C32: -7275177 | D32: 413180334 | E32: -290080130 | F32: -54659149 | G32: 480314685

Sheet Annual Dashboard
A1: EDITA FOOD INDUSTRIES — Annual Performance Dashboard
A4: EGP | B4: FY2021 | C4: FY2022 | D4: FY2023 | E4: FY2024 | F4: FY2025
A5: INCOME
A6: Revenue | B6: ='Income Statement'!E5 -> 5251215991 | C6: ='Income Statement'!I5 -> 7671100869 | D6: ='Income Statement'!M5 -> 12125997046 | E6: ='Income Statement'!Q5 -> 16146545699 | F6: ='Income Statement'!U5 -> 20915072432
A7: Gross profit | B7: ='Income Statement'!E7 -> 1673362472 | C7: ='Income Statement'!I7 -> 2607757782 | D7: ='Income Statement'!M7 -> 3925287329 | E7: ='Income Statement'!Q7 -> 4906312786 | F7: ='Income Statement'!U7 -> 7192057221
A8: PBT | B8: ='Income Statement'!E16 -> 634290716 | C8: ='Income Statement'!I16 -> 1270783958 | D8: ='Income Statement'!M16 -> 2050622094 | E8: ='Income Statement'!Q16 -> 1971704045 | F8: ='Income Statement'!U16 -> 3703837580
A9: Net profit | B9: ='Income Statement'!E18 -> 471903603 | C9: ='Income Statement'!I18 -> 959432071 | D9: ='Income Statement'!M18 -> 1506575439 | E9: ='Income Statement'!Q18 -> 1415374273 | F9: ='Income Statement'!U18 -> 2695301670
A11: MARGINS
A12: Gross margin % | B12: ='Financial Ratios'!E12 -> 0.3186619 | C12: ='Financial Ratios'!I12 -> 0.3399457 | D12: ='Financial Ratios'!M12 -> 0.32370842 | E12: ='Financial Ratios'!Q12 -> 0.30386145 | F12: ='Financial Ratios'!U12 -> 0.34386958
A13: Net margin % | B13: ='Financial Ratios'!E14 -> 0.089865586 | C13: ='Financial Ratios'!I14 -> 0.12507098 | D13: ='Financial Ratios'!M14 -> 0.12424343 | E13: ='Financial Ratios'!Q14 -> 0.087658023 | F13: ='Financial Ratios'!U14 -> 0.12886887
A15: GROWTH (YoY)
A16: Revenue growth % | B16: ='Financial Ratios'!E38 -> 0 | C16: ='Financial Ratios'!I38 -> 0.46082372 | D16: ='Financial Ratios'!M38 -> 0.58073753 | E16: ='Financial Ratios'!Q38 -> 0.33156438 | F16: ='Financial Ratios'!U38 -> 0.29532798
A17: Net profit growth % | B17: ='Financial Ratios'!E39 -> 0 | C17: ='Financial Ratios'!I39 -> 1.0331103 | D17: ='Financial Ratios'!M39 -> 0.57027838 | E17: ='Financial Ratios'!Q39 -> -0.060535413 | F17: ='Financial Ratios'!U39 -> 0.90430314
A19: CASH & LEVERAGE
A20: Operating cash flow | B20: ='Cash Flow'!B13 -> 311854466 | C20: ='Cash Flow'!C13 -> 861536860 | D20: ='Cash Flow'!D13 -> 1049280113 | E20: ='Cash Flow'!E13 -> 854487748 | F20: ='Cash Flow'!F13 -> 4311415865
A21: Net debt | B21: ='Financial Ratios'!E19 -> 1085337226 | C21: ='Financial Ratios'!I19 -> 1105790605 | D21: ='Financial Ratios'!M19 -> 1155298030 | E21: ='Financial Ratios'!Q19 -> 3181822264 | F21: ='Financial Ratios'!U19 -> 4284289091
A22: Net debt / Equity (x) | B22: ='Financial Ratios'!E21 -> 0.52685336 | C22: ='Financial Ratios'!I21 -> 0.41536994 | D22: ='Financial Ratios'!M21 -> 0.33950391 | E22: ='Financial Ratios'!Q21 -> 0.79205342 | F22: ='Financial Ratios'!U21 -> 0.70322794
