Workbook

Sheet Input_IS
A1: Quarterly line item | B1: 1Q21 | C1: 2Q21 | D1: 3Q21 | E1: 4Q21 | F1: 1Q22 | G1: 2Q22 | H1: 3Q22 | I1: 4Q22 | J1: 1Q23 | K1: 2Q23 | L1: 3Q23 | M1: 4Q23 | N1: 1Q24 | O1: 2Q24 | P1: 3Q24 | Q1: 4Q24 | R1: 1Q25 | S1: 2Q25 | T1: 3Q25 | U1: 4Q25 | V1: 1Q26
A2: Net sales | B2: =Source_IS_YTD!B3 -> 647085002 | C2: =Source_IS_YTD!C3-Source_IS_YTD!B3 -> 669915686 | D2: =Source_IS_YTD!D3-Source_IS_YTD!C3 -> 956091138 | E2: =Source_IS_YTD!E3-Source_IS_YTD!D3 -> 1087418279 | F2: =Source_IS_YTD!F3 -> 1121684905 | G2: =Source_IS_YTD!G3-Source_IS_YTD!F3 -> 1151921937 | H2: =Source_IS_YTD!H3-Source_IS_YTD!G3 -> 1618784913 | I2: =Source_IS_YTD!I3-Source_IS_YTD!H3 -> 1325481691 | J2: =Source_IS_YTD!J3 -> 1747362702 | K2: =Source_IS_YTD!K3-Source_IS_YTD!J3 -> 1573422003 | L2: =Source_IS_YTD!L3-Source_IS_YTD!K3 -> 2001158654 | M2: =Source_IS_YTD!M3-Source_IS_YTD!L3 -> 2182506511 | N2: =Source_IS_YTD!N3 -> 2282168947 | O2: =Source_IS_YTD!O3-Source_IS_YTD!N3 -> 2064394735 | P2: =Source_IS_YTD!P3-Source_IS_YTD!O3 -> 2543891873 | Q2: =Source_IS_YTD!Q3-Source_IS_YTD!P3 -> 2335518198 | R2: =Source_IS_YTD!R3 -> 2251517916 | S2: =Source_IS_YTD!S3-Source_IS_YTD!R3 -> 2004005941 | T2: =Source_IS_YTD!T3-Source_IS_YTD!S3 -> 2722870246 | U2: =Source_IS_YTD!U3-Source_IS_YTD!T3 -> 2412014296 | V2: =Source_IS_YTD!V3 -> 2559035323
A3: Cost of sales | B3: =Source_IS_YTD!B4 -> -514371833 | C3: =Source_IS_YTD!C4-Source_IS_YTD!B4 -> -529748694 | D3: =Source_IS_YTD!D4-Source_IS_YTD!C4 -> -733267728 | E3: =Source_IS_YTD!E4-Source_IS_YTD!D4 -> -830042306 | F3: =Source_IS_YTD!F4 -> -852271975 | G3: =Source_IS_YTD!G4-Source_IS_YTD!F4 -> -868134441 | H3: =Source_IS_YTD!H4-Source_IS_YTD!G4 -> -1017755998 | I3: =Source_IS_YTD!I4-Source_IS_YTD!H4 -> -1208467520 | J3: =Source_IS_YTD!J4 -> 0 | K3: =Source_IS_YTD!K4-Source_IS_YTD!J4 -> 0 | L3: =Source_IS_YTD!L4-Source_IS_YTD!K4 -> -4022489064 | M3: =Source_IS_YTD!M4-Source_IS_YTD!L4 -> -1902246188 | N3: =Source_IS_YTD!N4 -> -1788008019 | O3: =Source_IS_YTD!O4-Source_IS_YTD!N4 -> -1572324964 | P3: =Source_IS_YTD!P4-Source_IS_YTD!O4 -> -1931185725 | Q3: =Source_IS_YTD!Q4-Source_IS_YTD!P4 -> -1797018335 | R3: =Source_IS_YTD!R4 -> -1743543118 | S3: =Source_IS_YTD!S4-Source_IS_YTD!R4 -> -1536388550 | T3: =Source_IS_YTD!T4-Source_IS_YTD!S4 -> -2057323731 | U3: =Source_IS_YTD!U4-Source_IS_YTD!T4 -> -1780059187 | V3: =Source_IS_YTD!V4 -> -1935278800
A4: Selling and marketing expenses | B4: =Source_IS_YTD!B5 -> -120289255 | C4: =Source_IS_YTD!C5-Source_IS_YTD!B5 -> -135634503 | D4: =Source_IS_YTD!D5-Source_IS_YTD!C5 -> -145035872 | E4: =Source_IS_YTD!E5-Source_IS_YTD!D5 -> -166765245 | F4: =Source_IS_YTD!F5 -> -162744974 | G4: =Source_IS_YTD!G5-Source_IS_YTD!F5 -> -179968793 | H4: =Source_IS_YTD!H5-Source_IS_YTD!G5 -> -288616472 | I4: =Source_IS_YTD!I5-Source_IS_YTD!H5 -> -125955226 | J4: =Source_IS_YTD!J5 -> -209420407 | K4: =Source_IS_YTD!K5-Source_IS_YTD!J5 -> -230482112 | L4: =Source_IS_YTD!L5-Source_IS_YTD!K5 -> -232013315 | M4: =Source_IS_YTD!M5-Source_IS_YTD!L5 -> -63366353 | N4: =Source_IS_YTD!N5 -> -242606070 | O4: =Source_IS_YTD!O5-Source_IS_YTD!N5 -> -232067973 | P4: =Source_IS_YTD!P5-Source_IS_YTD!O5 -> -268568000 | Q4: =Source_IS_YTD!Q5-Source_IS_YTD!P5 -> -298434564 | R4: =Source_IS_YTD!R5 -> -247909481 | S4: =Source_IS_YTD!S5-Source_IS_YTD!R5 -> -401348842 | T4: =Source_IS_YTD!T5-Source_IS_YTD!S5 -> -414626235 | U4: =Source_IS_YTD!U5-Source_IS_YTD!T5 -> -455924139 | V4: =Source_IS_YTD!V5 -> -405466627
A5: General and administrative expenses | B5: =Source_IS_YTD!B6 -> -12881777 | C5: =Source_IS_YTD!C6-Source_IS_YTD!B6 -> -13497687 | D5: =Source_IS_YTD!D6-Source_IS_YTD!C6 -> -13479490 | E5: =Source_IS_YTD!E6-Source_IS_YTD!D6 -> -18804674 | F5: =Source_IS_YTD!F6 -> -18098216 | G5: =Source_IS_YTD!G6-Source_IS_YTD!F6 -> 13199815 | H5: =Source_IS_YTD!H6-Source_IS_YTD!G6 -> -61857534 | I5: =Source_IS_YTD!I6-Source_IS_YTD!H6 -> -18072894 | J5: =Source_IS_YTD!J6 -> -18097113 | K5: =Source_IS_YTD!K6-Source_IS_YTD!J6 -> -18609647 | L5: =Source_IS_YTD!L6-Source_IS_YTD!K6 -> -19045300 | M5: =Source_IS_YTD!M6-Source_IS_YTD!L6 -> -22303201 | N5: =Source_IS_YTD!N6 -> -21322676 | O5: =Source_IS_YTD!O6-Source_IS_YTD!N6 -> -23091038 | P5: =Source_IS_YTD!P6-Source_IS_YTD!O6 -> -22549558 | Q5: =Source_IS_YTD!Q6-Source_IS_YTD!P6 -> -27858712 | R5: =Source_IS_YTD!R6 -> -31325968 | S5: =Source_IS_YTD!S6-Source_IS_YTD!R6 -> -33945020 | T5: =Source_IS_YTD!T6-Source_IS_YTD!S6 -> -34414752 | U5: =Source_IS_YTD!U6-Source_IS_YTD!T6 -> -38967745 | V5: =Source_IS_YTD!V6 -> -27901748
A6: Net other operating income | B6: =Source_IS_YTD!B7 -> 10286699 | C6: =Source_IS_YTD!C7-Source_IS_YTD!B7 -> 2696781 | D6: =Source_IS_YTD!D7-Source_IS_YTD!C7 -> 10382872 | E6: =Source_IS_YTD!E7-Source_IS_YTD!D7 -> 13014792 | F6: =Source_IS_YTD!F7 -> 10496024 | G6: =Source_IS_YTD!G7-Source_IS_YTD!F7 -> 15790822 | H6: =Source_IS_YTD!H7-Source_IS_YTD!G7 -> 17912900 | I6: =Source_IS_YTD!I7-Source_IS_YTD!H7 -> 9091566 | J6: =Source_IS_YTD!J7 -> 13877478 | K6: =Source_IS_YTD!K7-Source_IS_YTD!J7 -> 28079469 | L6: =Source_IS_YTD!L7-Source_IS_YTD!K7 -> 38176669 | M6: =Source_IS_YTD!M7-Source_IS_YTD!L7 -> 31672755 | N6: =Source_IS_YTD!N7 -> 17126026 | O6: =Source_IS_YTD!O7-Source_IS_YTD!N7 -> 22531707 | P6: =Source_IS_YTD!P7-Source_IS_YTD!O7 -> 30677641 | Q6: =Source_IS_YTD!Q7-Source_IS_YTD!P7 -> 17143015 | R6: =Source_IS_YTD!R7 -> 32038633 | S6: =Source_IS_YTD!S7-Source_IS_YTD!R7 -> 28296741 | T6: =Source_IS_YTD!T7-Source_IS_YTD!S7 -> 33100904 | U6: =Source_IS_YTD!U7-Source_IS_YTD!T7 -> 29586628 | V6: =Source_IS_YTD!V7 -> 49369500
A7: Company share from investment in Associate | B7: =Source_IS_YTD!B8 -> 0 | C7: =Source_IS_YTD!C8-Source_IS_YTD!B8 -> 0 | D7: =Source_IS_YTD!D8-Source_IS_YTD!C8 -> 0 | E7: =Source_IS_YTD!E8-Source_IS_YTD!D8 -> 0 | F7: =Source_IS_YTD!F8 -> 0 | G7: =Source_IS_YTD!G8-Source_IS_YTD!F8 -> 0 | H7: =Source_IS_YTD!H8-Source_IS_YTD!G8 -> 0 | I7: =Source_IS_YTD!I8-Source_IS_YTD!H8 -> 0 | J7: =Source_IS_YTD!J8 -> 0 | K7: =Source_IS_YTD!K8-Source_IS_YTD!J8 -> 0 | L7: =Source_IS_YTD!L8-Source_IS_YTD!K8 -> 0 | M7: =Source_IS_YTD!M8-Source_IS_YTD!L8 -> -653158 | N7: =Source_IS_YTD!N8 -> 0 | O7: =Source_IS_YTD!O8-Source_IS_YTD!N8 -> 0 | P7: =Source_IS_YTD!P8-Source_IS_YTD!O8 -> 0 | Q7: =Source_IS_YTD!Q8-Source_IS_YTD!P8 -> -32614 | R7: =Source_IS_YTD!R8 -> 0 | S7: =Source_IS_YTD!S8-Source_IS_YTD!R8 -> 0 | T7: =Source_IS_YTD!T8-Source_IS_YTD!S8 -> 0 | U7: =Source_IS_YTD!U8-Source_IS_YTD!T8 -> 0 | V7: =Source_IS_YTD!V8 -> 0
A8: Provisions no longer required | B8: =Source_IS_YTD!B9 -> 0 | C8: =Source_IS_YTD!C9-Source_IS_YTD!B9 -> 0 | D8: =Source_IS_YTD!D9-Source_IS_YTD!C9 -> 0 | E8: =Source_IS_YTD!E9-Source_IS_YTD!D9 -> 0 | F8: =Source_IS_YTD!F9 -> 0 | G8: =Source_IS_YTD!G9-Source_IS_YTD!F9 -> 0 | H8: =Source_IS_YTD!H9-Source_IS_YTD!G9 -> 0 | I8: =Source_IS_YTD!I9-Source_IS_YTD!H9 -> 0 | J8: =Source_IS_YTD!J9 -> 0 | K8: =Source_IS_YTD!K9-Source_IS_YTD!J9 -> 0 | L8: =Source_IS_YTD!L9-Source_IS_YTD!K9 -> 0 | M8: =Source_IS_YTD!M9-Source_IS_YTD!L9 -> 5969392 | N8: =Source_IS_YTD!N9 -> 0 | O8: =Source_IS_YTD!O9-Source_IS_YTD!N9 -> 0 | P8: =Source_IS_YTD!P9-Source_IS_YTD!O9 -> 0 | Q8: =Source_IS_YTD!Q9-Source_IS_YTD!P9 -> 0 | R8: =Source_IS_YTD!R9 -> 0 | S8: =Source_IS_YTD!S9-Source_IS_YTD!R9 -> 0 | T8: =Source_IS_YTD!T9-Source_IS_YTD!S9 -> 0 | U8: =Source_IS_YTD!U9-Source_IS_YTD!T9 -> 22212609 | V8: =Source_IS_YTD!V9 -> 0
A9: Write-down / impairment | B9: =Source_IS_YTD!B10 -> 0 | C9: =Source_IS_YTD!C10-Source_IS_YTD!B10 -> 0 | D9: =Source_IS_YTD!D10-Source_IS_YTD!C10 -> 0 | E9: =Source_IS_YTD!E10-Source_IS_YTD!D10 -> 0 | F9: =Source_IS_YTD!F10 -> 0 | G9: =Source_IS_YTD!G10-Source_IS_YTD!F10 -> 0 | H9: =Source_IS_YTD!H10-Source_IS_YTD!G10 -> 0 | I9: =Source_IS_YTD!I10-Source_IS_YTD!H10 -> 0 | J9: =Source_IS_YTD!J10 -> 0 | K9: =Source_IS_YTD!K10-Source_IS_YTD!J10 -> 0 | L9: =Source_IS_YTD!L10-Source_IS_YTD!K10 -> 0 | M9: =Source_IS_YTD!M10-Source_IS_YTD!L10 -> 0 | N9: =Source_IS_YTD!N10 -> 0 | O9: =Source_IS_YTD!O10-Source_IS_YTD!N10 -> 0 | P9: =Source_IS_YTD!P10-Source_IS_YTD!O10 -> 0 | Q9: =Source_IS_YTD!Q10-Source_IS_YTD!P10 -> 0 | R9: =Source_IS_YTD!R10 -> 0 | S9: =Source_IS_YTD!S10-Source_IS_YTD!R10 -> 0 | T9: =Source_IS_YTD!T10-Source_IS_YTD!S10 -> 0 | U9: =Source_IS_YTD!U10-Source_IS_YTD!T10 -> -958044 | V9: =Source_IS_YTD!V10 -> 0
A10: Other provisions | B10: =Source_IS_YTD!B11 -> 0 | C10: =Source_IS_YTD!C11-Source_IS_YTD!B11 -> 0 | D10: =Source_IS_YTD!D11-Source_IS_YTD!C11 -> 0 | E10: =Source_IS_YTD!E11-Source_IS_YTD!D11 -> 0 | F10: =Source_IS_YTD!F11 -> 0 | G10: =Source_IS_YTD!G11-Source_IS_YTD!F11 -> 0 | H10: =Source_IS_YTD!H11-Source_IS_YTD!G11 -> 0 | I10: =Source_IS_YTD!I11-Source_IS_YTD!H11 -> 0 | J10: =Source_IS_YTD!J11 -> 0 | K10: =Source_IS_YTD!K11-Source_IS_YTD!J11 -> 0 | L10: =Source_IS_YTD!L11-Source_IS_YTD!K11 -> 0 | M10: =Source_IS_YTD!M11-Source_IS_YTD!L11 -> -42528993 | N10: =Source_IS_YTD!N11 -> 0 | O10: =Source_IS_YTD!O11-Source_IS_YTD!N11 -> 0 | P10: =Source_IS_YTD!P11-Source_IS_YTD!O11 -> 0 | Q10: =Source_IS_YTD!Q11-Source_IS_YTD!P11 -> -36334577 | R10: =Source_IS_YTD!R11 -> 0 | S10: =Source_IS_YTD!S11-Source_IS_YTD!R11 -> 0 | T10: =Source_IS_YTD!T11-Source_IS_YTD!S11 -> 0 | U10: =Source_IS_YTD!U11-Source_IS_YTD!T11 -> -14836690 | V10: =Source_IS_YTD!V11 -> -5710130
A11: Other operating items / balancing | B11: =Source_IS_YTD!B12 -> -346949 | C11: =Source_IS_YTD!C12-Source_IS_YTD!B12 -> 42170 | D11: =Source_IS_YTD!D12-Source_IS_YTD!C12 -> -153600 | E11: =Source_IS_YTD!E12-Source_IS_YTD!D12 -> 234523 | F11: =Source_IS_YTD!F12 -> -552700 | G11: =Source_IS_YTD!G12-Source_IS_YTD!F12 -> -30512700 | H11: =Source_IS_YTD!H12-Source_IS_YTD!G12 -> -170652700 | I11: =Source_IS_YTD!I12-Source_IS_YTD!H12 -> 183161498 | J11: =Source_IS_YTD!J12 -> -1294965696 | K11: =Source_IS_YTD!K12-Source_IS_YTD!J12 -> -1165280489 | L11: =Source_IS_YTD!L12-Source_IS_YTD!K12 -> 2440769012 | M11: =Source_IS_YTD!M12-Source_IS_YTD!L12 -> 19477173 | N11: =Source_IS_YTD!N12 -> -10992862 | O11: =Source_IS_YTD!O12-Source_IS_YTD!N12 -> -7769177 | P11: =Source_IS_YTD!P12-Source_IS_YTD!O12 -> -10075081 | Q11: =Source_IS_YTD!Q12-Source_IS_YTD!P12 -> 28837120 | R11: =Source_IS_YTD!R12 -> -102721579 | S11: =Source_IS_YTD!S12-Source_IS_YTD!R12 -> 99257968 | T11: =Source_IS_YTD!T12-Source_IS_YTD!S12 -> 13880133 | U11: =Source_IS_YTD!U12-Source_IS_YTD!T12 -> -10416522 | V11: =Source_IS_YTD!V12 -> -8
A12: Finance income | B12: =Source_IS_YTD!B13 -> 8152414 | C12: =Source_IS_YTD!C13-Source_IS_YTD!B13 -> 9200218 | D12: =Source_IS_YTD!D13-Source_IS_YTD!C13 -> 9792436 | E12: =Source_IS_YTD!E13-Source_IS_YTD!D13 -> 10004712 | F12: =Source_IS_YTD!F13 -> 8415675 | G12: =Source_IS_YTD!G13-Source_IS_YTD!F13 -> 6446968 | H12: =Source_IS_YTD!H13-Source_IS_YTD!G13 -> 9598683 | I12: =Source_IS_YTD!I13-Source_IS_YTD!H13 -> 14586926 | J12: =Source_IS_YTD!J13 -> 23181914 | K12: =Source_IS_YTD!K13-Source_IS_YTD!J13 -> 18423973 | L12: =Source_IS_YTD!L13-Source_IS_YTD!K13 -> 11961354 | M12: =Source_IS_YTD!M13-Source_IS_YTD!L13 -> 7818986 | N12: =Source_IS_YTD!N13 -> 20777958 | O12: =Source_IS_YTD!O13-Source_IS_YTD!N13 -> 13123072 | P12: =Source_IS_YTD!P13-Source_IS_YTD!O13 -> 9422631 | Q12: =Source_IS_YTD!Q13-Source_IS_YTD!P13 -> 9915273 | R12: =Source_IS_YTD!R13 -> 10451435 | S12: =Source_IS_YTD!S13-Source_IS_YTD!R13 -> 5705201 | T12: =Source_IS_YTD!T13-Source_IS_YTD!S13 -> 0 | U12: =Source_IS_YTD!U13-Source_IS_YTD!T13 -> 1249308 | V12: =Source_IS_YTD!V13 -> 2846843
A13: Finance expenses | B13: =Source_IS_YTD!B14 -> -19487746 | C13: =Source_IS_YTD!C14-Source_IS_YTD!B14 -> -25516245 | D13: =Source_IS_YTD!D14-Source_IS_YTD!C14 -> -27238588 | E13: =Source_IS_YTD!E14-Source_IS_YTD!D14 -> -24639086 | F13: =Source_IS_YTD!F14 -> -36058562 | G13: =Source_IS_YTD!G14-Source_IS_YTD!F14 -> -27372719 | H13: =Source_IS_YTD!H14-Source_IS_YTD!G14 -> -32270691 | I13: =Source_IS_YTD!I14-Source_IS_YTD!H14 -> -25281914 | J13: =Source_IS_YTD!J14 -> -60788910 | K13: =Source_IS_YTD!K14-Source_IS_YTD!J14 -> -69575540 | L13: =Source_IS_YTD!L14-Source_IS_YTD!K14 -> -77449097 | M13: =Source_IS_YTD!M14-Source_IS_YTD!L14 -> -76733444 | N13: =Source_IS_YTD!N14 -> -50398834 | O13: =Source_IS_YTD!O14-Source_IS_YTD!N14 -> -142327937 | P13: =Source_IS_YTD!P14-Source_IS_YTD!O14 -> -125551716 | Q13: =Source_IS_YTD!Q14-Source_IS_YTD!P14 -> -101692389 | R13: =Source_IS_YTD!R14 -> -145907163 | S13: =Source_IS_YTD!S14-Source_IS_YTD!R14 -> -150582657 | T13: =Source_IS_YTD!T14-Source_IS_YTD!S14 -> -120987527 | U13: =Source_IS_YTD!U14-Source_IS_YTD!T14 -> -93728335 | V13: =Source_IS_YTD!V14 -> -134215084
... A19: Earnings per share | B19: =Source_IS_YTD!B20 -> 0 | C19: =Source_IS_YTD!C20-Source_IS_YTD!B20 -> 0 | D19: =Source_IS_YTD!D20-Source_IS_YTD!C20 -> 0 | E19: =Source_IS_YTD!E20-Source_IS_YTD!D20 -> 0.209 | F19: =Source_IS_YTD!F20 -> 0 | G19: =Source_IS_YTD!G20-Source_IS_YTD!F20 -> 0 | H19: =Source_IS_YTD!H20-Source_IS_YTD!G20 -> 0 | I19: =Source_IS_YTD!I20-Source_IS_YTD!H20 -> 0.76 | J19: =Source_IS_YTD!J20 -> 0 | K19: =Source_IS_YTD!K20-Source_IS_YTD!J20 -> 0 | L19: =Source_IS_YTD!L20-Source_IS_YTD!K20 -> 0 | M19: =Source_IS_YTD!M20-Source_IS_YTD!L20 -> 1.3 | N19: =Source_IS_YTD!N20 -> 0.44 | O19: =Source_IS_YTD!O20-Source_IS_YTD!N20 -> 0.25 | P19: =Source_IS_YTD!P20-Source_IS_YTD!O20 -> 0.48 | Q19: =Source_IS_YTD!Q20-Source_IS_YTD!P20 -> 0.27 | R19: =Source_IS_YTD!R20 -> 0.03 | S19: =Source_IS_YTD!S20-Source_IS_YTD!R20 -> 0.013 | T19: =Source_IS_YTD!T20-Source_IS_YTD!S20 -> 0.287 | U19: =Source_IS_YTD!U20-Source_IS_YTD!T20 -> 0.13 | V19: =Source_IS_YTD!V20 -> 0.2

Sheet Input_BS
A1: Raw extracted line item | B1: 1Q21 | C1: 2Q21 | D1: 3Q21 | E1: 4Q21 | F1: 1Q22 | G1: 2Q22 | H1: 3Q22 | I1: 4Q22 | J1: 1Q23 | K1: 2Q23 | L1: 3Q23 | M1: 4Q23 | N1: 1Q24 | O1: 2Q24 | P1: 3Q24 | Q1: 4Q24 | R1: 1Q25 | S1: 2Q25 | T1: 3Q25 | U1: 4Q25 | V1: 1Q26
A2: Property, plant and equipment | B2: 580716667 | C2: 680979431 | D2: 742771604 | E2: 730770964 | F2: 709089656 | G2: 686911526 | H2: 702438044 | I2: 693270370 | J2: 672151438 | K2: 749876972 | L2: 725908951 | M2: 776875848 | N2: 777075980 | O2: 795926750 | P2: 785832180 | Q2: 811770762 | R2: 949274112 | S2: 922412917 | T2: 968233533 | U2: 989890873 | V2: 775409439
A3: Projects under construction | B3: 194092151 | C3: 109649645 | D3: 28446645 | E3: 2487907 | F3: 56001562 | G3: 61003069 | H3: 51373180 | I3: 102537315 | J3: 128895956 | K3: 88123214 | L3: 100624381 | M3: 38909533 | N3: 72462022 | O3: 175730482 | P3: 205091605 | Q3: 197596471 | R3: 159402306 | S3: 173152041 | T3: 122350826 | U3: 89102731 | V3: 90000322
A4: Investments in associate | B4: 0 | C4: 0 | D4: 0 | E4: 0 | F4: 0 | G4: 0 | H4: 0 | I4: 0 | J4: 0 | K4: 0 | L4: 0 | M4: 3365395 | N4: 3365395 | O4: 3365395 | P4: 3365395 | Q4: 0 | R4: 0 | S4: 0 | T4: 0 | U4: 0 | V4: 0
A5: Investment in subsidiary | B5: 0 | C5: 0 | D5: 0 | E5: 0 | F5: 0 | G5: 0 | H5: 0 | I5: 0 | J5: 0 | K5: 0 | L5: 0 | M5: 0 | N5: 0 | O5: 0 | P5: 0 | Q5: 0 | R5: 0 | S5: 0 | T5: 0 | U5: 0 | V5: 72502733
A6: Other non-current assets / balancing | B6: 0 | C6: 0 | D6: 4629853 | E6: 54629853 | F6: 4629853 | G6: 4629853 | H6: -753811224 | I6: 4018553 | J6: 104018553 | K6: 4155415 | L6: 4155415 | M6: 0 | N6: 0 | O6: -974999020 | P6: 0 | Q6: 0 | R6: 0 | S6: 0 | T6: 0 | U6: 0 | V6: 0
A7: Inventories | B7: 357787229 | C7: 439773442 | D7: 494319945 | E7: 14255299 | F7: 15842107 | G7: 716197484 | H7: 0 | I7: 572087082 | J7: 755206928 | K7: 712189945 | L7: 687384207 | M7: 894981615 | N7: 1139385610 | O7: 4174473687 | P7: 1053367544 | Q7: 1233048891 | R7: 0 | S7: 1465216424 | T7: 1080034913 | U7: 1250611372 | V7: 1194680642
A8: Accounts and notes receivable | B8: 610803432 | C8: 576907582 | D8: 669512956 | E8: 637237807 | F8: 686879995 | G8: 779953345 | H8: 0 | I8: 591657820 | J8: 0 | K8: 847346753 | L8: 988549365 | M8: 938184238 | N8: 1224208460 | O8: 231628902 | P8: 0 | Q8: 1307396997 | R8: 1562872775 | S8: 1353994231 | T8: 1528959846 | U8: 1526519565 | V8: 1800636217
A9: Prepayments and other debit balances / balancing | B9: 495455767 | C9: 505746612 | D9: 518535034 | E9: 957804744 | F9: 1005759600 | G9: 510256601 | H9: -264146556 | I9: 695386168 | J9: 1609946301 | K9: 654150356 | L9: 443603657 | M9: 434976393 | N9: 879563603 | O9: -1504177669 | P9: 1905769483 | Q9: 574627117 | R9: 2184098077 | S9: 456607125 | T9: 388344339 | U9: 450154473 | V9: 691837974
A10: Financial investment at amortized cost - treasury bills | B10: 0 | C10: 0 | D10: 0 | E10: 0 | F10: 0 | G10: 0 | H10: 0 | I10: 0 | J10: 0 | K10: 0 | L10: 0 | M10: 0 | N10: 0 | O10: 0 | P10: 0 | Q10: 0 | R10: 0 | S10: 0 | T10: 0 | U10: 0 | V10: 0
A11: Cash on hand and at banks | B11: 125038404 | C11: 128075432 | D11: 132770425 | E11: 163942106 | F11: 177666199 | G11: 205680242 | H11: 264146556 | I11: 440158488 | J11: 381407058 | K11: 219936811 | L11: 542098898 | M11: 522517539 | N11: 279255117 | O11: 474252647 | P11: 520423136 | Q11: 595006347 | R11: 521552628 | S11: 271483760 | T11: 174356463 | U11: 618922303 | V11: 319665548
A12: Issued and paid-up capital | B12: 56521739 | C12: 56521739 | D12: 56521739 | E12: 56521739 | F12: 56521739 | G12: 56521739 | H12: 56521739 | I12: 56521739 | J12: 56521739 | K12: 56521739 | L12: 56521739 | M12: 56521739 | N12: 56521739 | O12: 56521739 | P12: 56521739 | Q12: 56521739 | R12: 56521739 | S12: 56521739 | T12: 56521739 | U12: 56521739 | V12: 56521739
A13: Legal reserve | B13: 28260870 | C13: 28260870 | D13: 28260870 | E13: 28260870 | F13: 28260870 | G13: 28260870 | H13: 28260870 | I13: 28260870 | J13: 28260870 | K13: 28260870 | L13: 28260870 | M13: 28260870 | N13: 28260870 | O13: 28260870 | P13: 28260870 | Q13: 28260870 | R13: 28260870 | S13: 28260870 | T13: 28260870 | U13: 28260870 | V13: 28260870
... A29: Other current liabilities / balancing | B29: 243070542 | C29: -868597269 | D29: 148728398 | E29: 150285163 | F29: 205819742 | G29: 213311907 | H29: -1582547794 | I29: 299843026 | J29: 0 | K29: 1667399245 | L29: 444506323 | M29: 414580238 | N29: 518322787 | O29: 770398907 | P29: -4561640081 | Q29: 428559424 | R29: 454802914 | S29: 275476540 | T29: 299168580 | U29: 320797920 | V29: 404537295

Sheet Input_CF
A1: Quarterly line item | B1: 1Q21 | C1: 2Q21 | D1: 3Q21 | E1: 4Q21 | F1: 1Q22 | G1: 2Q22 | H1: 3Q22 | I1: 4Q22 | J1: 1Q23 | K1: 2Q23 | L1: 3Q23 | M1: 4Q23 | N1: 1Q24 | O1: 2Q24 | P1: 3Q24 | Q1: 4Q24 | R1: 1Q25 | S1: 2Q25 | T1: 3Q25 | U1: 4Q25 | V1: 1Q26
A2: Net cash flows from operating activities | B2: =Source_CF_YTD!B3 -> 20580943 | C2: =Source_CF_YTD!C3-Source_CF_YTD!B3 -> 3037028 | D2: =Source_CF_YTD!D3-Source_CF_YTD!C3 -> 4694993 | E2: =Source_CF_YTD!E3-Source_CF_YTD!D3 -> 31171681 | F2: =Source_CF_YTD!F3 -> 1593999 | G2: =Source_CF_YTD!G3-Source_CF_YTD!F3 -> -219712930 | H2: =Source_CF_YTD!H3-Source_CF_YTD!G3 -> 217910417 | I2: =Source_CF_YTD!I3-Source_CF_YTD!H3 -> 272760010 | J2: =Source_CF_YTD!J3 -> -236840190 | K2: =Source_CF_YTD!K3-Source_CF_YTD!J3 -> 128361544 | L2: =Source_CF_YTD!L3-Source_CF_YTD!K3 -> 110867727 | M2: =Source_CF_YTD!M3-Source_CF_YTD!L3 -> -2389081 | N2: =Source_CF_YTD!N3 -> -243262422 | O2: =Source_CF_YTD!O3-Source_CF_YTD!N3 -> 194997530 | P2: =Source_CF_YTD!P3-Source_CF_YTD!O3 -> 46170489 | Q2: =Source_CF_YTD!Q3-Source_CF_YTD!P3 -> -72696575 | R2: =Source_CF_YTD!R3 -> -73453719 | S2: =Source_CF_YTD!S3-Source_CF_YTD!R3 -> -494066868 | T2: =Source_CF_YTD!T3-Source_CF_YTD!S3 -> 969460543 | U2: =Source_CF_YTD!U3-Source_CF_YTD!T3 -> -174993354 | V2: =Source_CF_YTD!V3 -> -299256755
A3: Net cash flows from investing activities | B3: =Source_CF_YTD!B4 -> 0 | C3: =Source_CF_YTD!C4-Source_CF_YTD!B4 -> 0 | D3: =Source_CF_YTD!D4-Source_CF_YTD!C4 -> 0 | E3: =Source_CF_YTD!E4-Source_CF_YTD!D4 -> 0 | F3: =Source_CF_YTD!F4 -> -4731973 | G3: =Source_CF_YTD!G4-Source_CF_YTD!F4 -> 5702332 | H3: =Source_CF_YTD!H4-Source_CF_YTD!G4 -> 41475844 | I3: =Source_CF_YTD!I4-Source_CF_YTD!H4 -> -291785165 | J3: =Source_CF_YTD!J4 -> 0 | K3: =Source_CF_YTD!K4-Source_CF_YTD!J4 -> 38193097 | L3: =Source_CF_YTD!L4-Source_CF_YTD!K4 -> 247894184 | M3: =Source_CF_YTD!M4-Source_CF_YTD!L4 -> -285466725 | N3: =Source_CF_YTD!N4 -> 0 | O3: =Source_CF_YTD!O4-Source_CF_YTD!N4 -> 0 | P3: =Source_CF_YTD!P4-Source_CF_YTD!O4 -> 0 | Q3: =Source_CF_YTD!Q4-Source_CF_YTD!P4 -> -403186273 | R3: =Source_CF_YTD!R4 -> 0 | S3: =Source_CF_YTD!S4-Source_CF_YTD!R4 -> 0 | T3: =Source_CF_YTD!T4-Source_CF_YTD!S4 -> 51457743 | U3: =Source_CF_YTD!U4-Source_CF_YTD!T4 -> -11965437 | V3: =Source_CF_YTD!V4 -> 0
A4: Net cash flows from financing activities | B4: =Source_CF_YTD!B5 -> 0 | C4: =Source_CF_YTD!C5-Source_CF_YTD!B5 -> 0 | D4: =Source_CF_YTD!D5-Source_CF_YTD!C5 -> 0 | E4: =Source_CF_YTD!E5-Source_CF_YTD!D5 -> 0 | F4: =Source_CF_YTD!F5 -> 23914398 | G4: =Source_CF_YTD!G5-Source_CF_YTD!F5 -> 229972310 | H4: =Source_CF_YTD!H5-Source_CF_YTD!G5 -> 13086482 | I4: =Source_CF_YTD!I5-Source_CF_YTD!H5 -> -13969342 | J4: =Source_CF_YTD!J5 -> 222300809 | K4: =Source_CF_YTD!K5-Source_CF_YTD!J5 -> -303729063 | L4: =Source_CF_YTD!L5-Source_CF_YTD!K5 -> -20725804 | M4: =Source_CF_YTD!M5-Source_CF_YTD!L5 -> 102154058 | N4: =Source_CF_YTD!N5 -> 0 | O4: =Source_CF_YTD!O5-Source_CF_YTD!N5 -> 0 | P4: =Source_CF_YTD!P5-Source_CF_YTD!O5 -> 0 | Q4: =Source_CF_YTD!Q5-Source_CF_YTD!P5 -> 432355005 | R4: =Source_CF_YTD!R5 -> 0 | S4: =Source_CF_YTD!S5-Source_CF_YTD!R5 -> 0 | T4: =Source_CF_YTD!T5-Source_CF_YTD!S5 -> -718428728 | U4: =Source_CF_YTD!U5-Source_CF_YTD!T5 -> 648254366 | V4: =Source_CF_YTD!V5 -> 0
A5: Foreign exchange / residual effect | B5: =Source_CF_YTD!B6 -> 0 | C5: =Source_CF_YTD!C6-Source_CF_YTD!B6 -> 0 | D5: =Source_CF_YTD!D6-Source_CF_YTD!C6 -> 0 | E5: =Source_CF_YTD!E6-Source_CF_YTD!D6 -> 0 | F5: =Source_CF_YTD!F6 -> -7052331 | G5: =Source_CF_YTD!G6-Source_CF_YTD!F6 -> 12052331 | H5: =Source_CF_YTD!H6-Source_CF_YTD!G6 -> -214006429 | I5: =Source_CF_YTD!I6-Source_CF_YTD!H6 -> 209006429 | J5: =Source_CF_YTD!J6 -> -44212049 | K5: =Source_CF_YTD!K6-Source_CF_YTD!J6 -> -24295825 | L5: =Source_CF_YTD!L6-Source_CF_YTD!K6 -> -14974020 | M5: =Source_CF_YTD!M6-Source_CF_YTD!L6 -> 165220389 | N5: =Source_CF_YTD!N6 -> 0 | O5: =Source_CF_YTD!O6-Source_CF_YTD!N6 -> 0 | P5: =Source_CF_YTD!P6-Source_CF_YTD!O6 -> 0 | Q5: =Source_CF_YTD!Q6-Source_CF_YTD!P6 -> 118111054 | R5: =Source_CF_YTD!R6 -> 0 | S5: =Source_CF_YTD!S6-Source_CF_YTD!R6 -> 0 | T5: =Source_CF_YTD!T6-Source_CF_YTD!S6 -> -155618855 | U5: =Source_CF_YTD!U6-Source_CF_YTD!T6 -> -16729645 | V5: =Source_CF_YTD!V6 -> 0
A6: Cash and cash equivalents - beginning | B6: =Source_CF_YTD!B7 -> 104457461 | C6: =Source_CF_YTD!B8 -> 125038404 | D6: =Source_CF_YTD!C8 -> 128075432 | E6: =Source_CF_YTD!D8 -> 132770425 | F6: =Source_CF_YTD!F7 -> 163942106 | G6: =Source_CF_YTD!F8 -> 177666199 | H6: =Source_CF_YTD!G8 -> 205680242 | I6: =Source_CF_YTD!H8 -> 264146556 | J6: =Source_CF_YTD!J7 -> 440158488 | K6: =Source_CF_YTD!J8 -> 381407058 | L6: =Source_CF_YTD!K8 -> 219936811 | M6: =Source_CF_YTD!L8 -> 542998898 | N6: =Source_CF_YTD!N7 -> 522517539 | O6: =Source_CF_YTD!N8 -> 279255117 | P6: =Source_CF_YTD!O8 -> 474252647 | Q6: =Source_CF_YTD!P8 -> 520423136 | R6: =Source_CF_YTD!R7 -> 595006347 | S6: =Source_CF_YTD!R8 -> 521552628 | T6: =Source_CF_YTD!S8 -> 27485760 | U6: =Source_CF_YTD!T8 -> 174356463 | V6: =Source_CF_YTD!V7 -> 618922303
A7: Cash and cash equivalents - end (source) | B7: =Source_CF_YTD!B8 -> 125038404 | C7: =Source_CF_YTD!C8 -> 128075432 | D7: =Source_CF_YTD!D8 -> 132770425 | E7: =Source_CF_YTD!E8 -> 163942106 | F7: =Source_CF_YTD!F8 -> 177666199 | G7: =Source_CF_YTD!G8 -> 205680242 | H7: =Source_CF_YTD!H8 -> 264146556 | I7: =Source_CF_YTD!I8 -> 440158488 | ... V7: =Source_CF_YTD!V8 -> 319665548

Sheet Income Statement
A1: Domty — Quarterly Income Statement (EGP) | B1: 1Q21 | C1: 2Q21 | D1: 3Q21 | E1: FY21 | F1: 1Q22 | G1: 2Q22 | H1: 3Q22 | I1: FY22 | J1: 1Q23 | K1: 2Q23 | L1: 3Q23 | M1: FY23 | N1: 1Q24 | O1: 2Q24 | P1: 3Q24 | Q1: FY24 | R1: 1Q25 | S1: 2Q25 | T1: 3Q25 | U1: FY25 | V1: 1Q26
A2: Revenue | B2: =Input_IS!B2 -> 647085002 | C2: =Input_IS!C2 -> 669915686 | D2: =Input_IS!D2 -> 956091138 | E2: 3360510105 | F2: =Input_IS!F2 -> 1121684905 | G2: =Input_IS!G2 -> 1151921937 | H2: 1318784913 | I2: 5217873446 | J2: =Input_IS!J2 -> 1747362702 | K2: =Input_IS!K2 -> 1573422003 | L2: =Input_IS!L2 -> 2001158654 | M2: 7504449870 | N2: =Input_IS!N2 -> 2282168947 | O2: =Input_IS!O2 -> 2064394735 | P2: =Input_IS!P2 -> 2543891873 | Q2: 9225973753 | R2: =Input_IS!R2 -> 2251517916 | S2: =Input_IS!S2 -> 2004005941 | T2: =Input_IS!T2 -> 2722870246 | U2: 9390408399 | V2: =Input_IS!V2 -> 2559035323
A3: Cost of sales | B3: =Input_IS!B3 -> -514371833 | C3: =Input_IS!C3 -> -529748694 | D3: =Input_IS!D3 -> -733267728 | E3: -2607430561 | F3: =Input_IS!F3 -> -852271975 | G3: =Input_IS!G3 -> -868134441 | H3: =Input_IS!H3 -> -1017755998 | I3: -3946629934 | J3: -1292654264 | K3: -1163317190 | L3: -1566517610 | M3: -5924735252 | N3: =Input_IS!N3 -> -1788008019 | O3: =Input_IS!O3 -> -1572324964 | P3: =Input_IS!P3 -> -1931185725 | Q3: -7088537043 | R3: =Input_IS!R3 -> -1743543118 | S3: =Input_IS!S3 -> -1536388550 | T3: =Input_IS!T3 -> -2057323731 | U3: -7117314586 | V3: =Input_IS!V3 -> -1935278800
A4: Gross profit | B4: =B2+B3 -> 132713169 | C4: =C2+C3 -> 140166992 | D4: =D2+D3 -> 222823410 | E4: 753079544 | F4: =F2+F3 -> 269412930 | G4: =G2+G3 -> 283787496 | H4: =H2+H3 -> 301028915 | I4: =SUM(I2:I3) -> 1271243512 | J4: =J2+J3 -> 454708438 | K4: =K2+K3 -> 410104813 | L4: =L2+L3 -> 434641044 | M4: =SUM(M2:M3) -> 1579714618 | N4: =N2+N3 -> 494160928 | O4: =O2+O3 -> 492069771 | P4: =P2+P3 -> 612706148 | Q4: =SUM(Q2:Q3) -> 2137436710 | R4: =R2+R3 -> 507974798 | S4: =S2+S3 -> 467617391 | T4: =T2+T3 -> 665546515 | U4: =SUM(U2:U3) -> 2273093813 | V4: =V2+V3 -> 623756523
A5: Gross margin % | B5: =IFERROR(B4/B2,0) -> 0.20509387 | C5: =IFERROR(C4/C2,0) -> 0.2092308 | D5: =IFERROR(D4/D2,0) -> 0.23305666 | E5: =E4/E2 -> 0.22409679 | F5: =IFERROR(F4/F2,0) -> 0.24018593 | G5: =IFERROR(G4/G2,0) -> 0.24636001 | H5: =IFERROR(H4/H2,0) -> 0.22826233 | I5: 0.19749258 | J5: =IFERROR(J4/J2,0) -> 0.26022556 | K5: =IFERROR(K4/K2,0) -> 0.26064515 | L5: =IFERROR(L4/L2,0) -> 0.2171947 | M5: =IFERROR(M4/M2,0) -> 0.21050372 | N5: =IFERROR(N4/N2,0) -> 0.21653126 | O5: =IFERROR(O4/O2,0) -> 0.23836031 | P5: =IFERROR(P4/P2,0) -> 0.24085385 | Q5: =IFERROR(Q4/Q2,0) -> 0.231676 | ... V5: =IFERROR(V4/V2,0) -> 0.24374674
A6: Operating expenses / income | E6: 0 | I6: 0 | M6: -735282187
A7: Selling and marketing expenses | B7: =Input_IS!B4 -> -120289255 | C7: =Input_IS!C4 -> -135634503 | D7: =Input_IS!D4 -> -145035872 | E7: -567724875 | F7: =Input_IS!F4 -> -162744974 | G7: =Input_IS!G4 -> -179968793 | H7: -188616472 | I7: -757285465 | J7: =Input_IS!J4 -> -209420407 | K7: =Input_IS!K4 -> -230482112 | L7: =Input_IS!L4 -> -232013315 | M7: -78055261 | N7: =Input_IS!N4 -> -242606070 | O7: =Input_IS!O4 -> -232067973 | P7: =Input_IS!P4 -> -268568000 | Q7: -1041676607 | R7: -347909441 | S7: -301348882 | T7: =Input_IS!T4 -> -414626235 | U7: -1519808697 | V7: =Input_IS!V4 -> -405466627
A8: General and administrative expenses | B8: =Input_IS!B5 -> -12881777 | C8: =Input_IS!C5 -> -13497687 | D8: =Input_IS!D5 -> -13479490 | E8: -58663628 | F8: =Input_IS!F5 -> -18098216 | G8: =Input_IS!G5 -> 13199815 | H8: -31857534 | I8: -84828829 | J8: =Input_IS!J5 -> -18097113 | K8: =Input_IS!K5 -> -18609647 | L8: =Input_IS!L5 -> -19045300 | M8: 111806371 | N8: =Input_IS!N5 -> -21322676 | O8: =-23091039 -> -23091039 | P8: =Input_IS!P5 -> -22549558 | Q8: -94821984 | R8: -31325988 | S8: -33945000 | T8: =Input_IS!T5 -> -34414752 | U8: -138653485 | V8: =Input_IS!V5 -> -27901748
A9: Net other operating income | B9: =Input_IS!B6 -> 10286699 | C9: =Input_IS!C6 -> 2696781 | D9: =Input_IS!D6 -> 10382872 | E9: 36381144 | F9: =Input_IS!F6 -> 10496024 | G9: =Input_IS!G6 -> 15790822 | H9: =Input_IS!H6 -> 17912900 | I9: 53291312 | J9: 13577478 | K9: 34379469 | L9: 32176669 | M9: 5969392 | N9: =Input_IS!N6 -> 17126026 | O9: =Input_IS!O6 -> 22531707 | P9: =Input_IS!P6 -> 30677641 | Q9: 87478389 | R9: 32038833 | S9: 28296541 | T9: =Input_IS!T6 -> 33100904 | U9: 123022906 | V9: =Input_IS!V6 -> 49369500
A10: Company share from investment in Associate | B10: =Input_IS!B7 -> 0 | C10: =Input_IS!C7 -> 0 | D10: =Input_IS!D7 -> 0 | E10: 0 | F10: =Input_IS!F7 -> 0 | G10: =Input_IS!G7 -> 0 | H10: =Input_IS!H7 -> 0 | I10: 0 | J10: 561268 | K10: 136862 | L10: =Input_IS!L7 -> 0 | M10: -653158 | N10: =Input_IS!N7 -> 0 | O10: =Input_IS!O7 -> 0 | P10: =Input_IS!P7 -> 0 | Q10: -32614 | R10: =Input_IS!R7 -> 0 | S10: =Input_IS!S7 -> 0 | T10: 21667172 | V10: =Input_IS!V7 -> 0
A11: Provisions no longer required | B11: =Input_IS!B8 -> 0 | C11: =Input_IS!C8 -> 0 | D11: =Input_IS!D8 -> 0 | E11: 0 | F11: =Input_IS!F8 -> 0 | G11: =Input_IS!G8 -> 0 | H11: -652700 | I11: -611300 | J11: -2572700 | K11: 725602 | L11: 4408862 | N11: =Input_IS!N8 -> 0 | O11: =Input_IS!O8 -> 0 | P11: =Input_IS!P8 -> 0 | R11: =Input_IS!R8 -> 0 | S11: =Input_IS!S8 -> 0 | T11: -958044 | U11: 22212609 | V11: =Input_IS!V8 -> 0
A12: Write-down / impairment | B12: =Input_IS!B9 -> 0 | C12: =Input_IS!C9 -> 0 | D12: =Input_IS!D9 -> 0 | E12: 0 | F12: =Input_IS!F9 -> 0 | G12: =Input_IS!G9 -> 0 | H12: =Input_IS!H9 -> 0 | I12: -584502 | J12: =Input_IS!J9 -> 0 | K12: =Input_IS!K9 -> 0 | L12: =Input_IS!L9 -> 0 | N12: -181283 | O12: -1357109 | P12: =Input_IS!P9 -> 0 | R12: =Input_IS!R9 -> 0 | S12: =Input_IS!S9 -> 0 | U12: -958044 | V12: =Input_IS!V9 -> 0
A13: Other provisions | B13: =Input_IS!B10 -> 0 | C13: =Input_IS!C10 -> 0 | D13: =Input_IS!D10 -> 0 | E13: 0 | F13: =Input_IS!F10 -> 0 | G13: =Input_IS!G10 -> 0 | H13: =Input_IS!H10 -> 0 | I13: -17360800 | J13: =Input_IS!J10 -> 0 | K13: -9125763 | L13: -13611304 | M13: -42528993 | N13: -10811579 | O13: -6412087 | P13: =Input_IS!P10 -> 0 | Q13: -36334577 | R13: -1921799 | S13: -1541812 | T13: -6828995 | U13: -14836690 | V13: =Input_IS!V10 -> -5710130
A14: Other operating items / balancing | B14: =Input_IS!B11 -> -346949 | C14: =Input_IS!C11 -> 42170 | D14: =Input_IS!D11 -> -153600 | E14: -223856 | F14: =Input_IS!F11 -> -552700 | G14: =Input_IS!G11 -> -30512700 | H14: 0 | I14: 0 | J14: 0 | K14: 0 | L14: 0 | M14: 0 | N14: 0 | O14: 0 | P14: =Input_IS!P11 -> -10075081 | Q14: 0 | R14: 0 | V14: =Input_IS!V11 -> -8
A15: Operating profit | B15: =B4+SUM(B7:B14) -> 9481887 | C15: =C4+SUM(C7:C14) -> -6226247 | D15: =D4+SUM(D7:D14) -> 74537320 | E15: 162848329 | F15: =F4+SUM(F7:F14) -> 98513064 | G15: =G4+SUM(G7:G14) -> 102296640 | H15: =H4+SUM(H7:H14) -> 97815109 | I15: =I4+SUM(I7:I14) -> 463863928 | J15: =J4+SUM(J7:J14) -> 238756964 | K15: =K4+SUM(K7:K14) -> 187129224 | L15: =L4+SUM(L7:L14) -> 206556656 | M15: =M4+SUM(M6:M14) -> 840970782 | N15: =N4+SUM(N7:N14) -> 236365346 | O15: =O4+SUM(O7:O14) -> 251673270 | P15: =P4+SUM(P7:P14) -> 342191150 | Q15: =Q4+SUM(Q7:Q14) -> 1052049317 | R15: =R4+SUM(R7:R14) -> 158856403 | S15: =S4+SUM(S7:S14) -> 159078238 | T15: =T4+SUM(T7:T14) -> 263486565 | U15: =U4+SUM(U7:U14) -> 744072412 | V15: =V4+SUM(V7:V14) -> 234047510
A16: Operating margin % | B16: =IFERROR(B15/B2,0) -> 0.014653233 | C16: =IFERROR(C15/C2,0) -> -0.0092940756 | D16: =IFERROR(D15/D2,0) -> 0.077960476 | E16: =E15/E2 -> 0.048459408 | F16: =IFERROR(F15/F2,0) -> 0.087825969 | G16: =IFERROR(G15/G2,0) -> 0.088805184 | H16: =IFERROR(H15/H2,0) -> 0.074170631 | I16: =I15/I2 -> 0.088899038 | J16: =IFERROR(J15/J2,0) -> 0.13663847 | K16: =IFERROR(K15/K2,0) -> 0.11893136 | L16: =IFERROR(L15/L2,0) -> 0.10321853 | M16: =IFERROR(M15/M2,0) -> 0.11206295 | N16: =IFERROR(N15/N2,0) -> 0.10357049 | O16: =IFERROR(O15/O2,0) -> 0.12191141 | P16: =IFERROR(P15/P2,0) -> 0.13451482 | Q16: =IFERROR(Q15/Q2,0) -> 0.11403125 | ... V16: =IFERROR(V15/V2,0) -> 0.091459273
A17: Finance, tax and net income | B17: =Input_IS!B9 -> 0 | C17: =Input_IS!C9 -> 0 | D17: =Input_IS!D9 -> 0 | E17: 0 | F17: =Input_IS!F9 -> 0 | G17: =Input_IS!G9 -> 0 | H17: =Input_IS!H9 -> 0 | I17: 0 | J17: =Input_IS!J9 -> 0 | K17: =Input_IS!K9 -> 0 | L17: =Input_IS!L9 -> 0 | N17: =Input_IS!N9 -> 0 | O17: =Input_IS!O9 -> 0 | P17: =Input_IS!P9 -> 0 | R17: =Input_IS!R9 -> 0 | S17: =Input_IS!S9 -> 0 | T17: =Input_IS!T9 -> 0 | V17: =Input_IS!V9 -> 0
A18: Finance income | B18: =Input_IS!B12 -> 8152414 | C18: =Input_IS!C12 -> 9200218 | D18: =Input_IS!D12 -> 9792436 | E18: 37149780 | F18: =Input_IS!F12 -> 8415675 | G18: =Input_IS!G12 -> 6446968 | H18: =Input_IS!H12 -> 9598683 | I18: 39048252 | J18: =Input_IS!J12 -> 23181914 | K18: =Input_IS!K12 -> 18423973 | L18: =Input_IS!L12 -> 11961354 | M18: 61386227 | N18: =Input_IS!N12 -> 20777958 | O18: =Input_IS!O12 -> 13123072 | P18: =Input_IS!P12 -> 9422631 | Q18: 53238934 | R18: 10451435 | S18: =Input_IS!S12 -> 5705201 | T18: =Input_IS!T12 -> 0 | U18: 17405944 | V18: =Input_IS!V12 -> 2846843
A19: Finance expenses | B19: =Input_IS!B13 -> -19487746 | C19: =Input_IS!C13 -> -25516245 | D19: =Input_IS!D13 -> -27238588 | E19: -96881665 | F19: =Input_IS!F13 -> -36058562 | G19: =Input_IS!G13 -> -27372719 | H19: =Input_IS!H13 -> -32270691 | I19: -120983886 | J19: =Input_IS!J13 -> -60788910 | K19: =Input_IS!K13 -> -69575540 | L19: =Input_IS!L13 -> -77449097 | M19: -284546991 | N19: =Input_IS!N13 -> -50398834 | O19: =Input_IS!O13 -> -142327937 | P19: =Input_IS!P13 -> -125551716 | Q19: -419970876 | R19: =Input_IS!R13 -> -145907163 | S19: =Input_IS!S13 -> -150582657 | T19: =Input_IS!T13 -> -120987527 | U19: -511205682 | V19: =Input_IS!V13 -> -134215084
A20: Loss on sale / other finance items | B20: =Input_IS!B14 -> 0 | C20: =Input_IS!C14 -> 0 | D20: =Input_IS!D14 -> 0 | E20: 0 | F20: =Input_IS!F14 -> 0 | I20: -17876887 | L20: =Input_IS!L14 -> 0 | N20: =Input_IS!N14 -> 0 | O20: =Input_IS!O14 -> 0 | P20: =Input_IS!P14 -> 0 | T20: =Input_IS!T14 -> 0 | V20: =Input_IS!V14 -> 0
A21: Contribution / comprehensive insurance / solidarity | B21: =Input_IS!B15 -> 0 | C21: -1739273 | D21: -2482598 | E21: -8741557 | F21: -2889888 | G21: -2976758 | H21: -3404892 | I21: -13428920 | J21: -4489921 | K21: -4099534 | L21: -5314781 | M21: -19996861 | N21: -6091471 | O21: -5505928 | P21: -6778789 | Q21: -24619577 | R21: -6022481 | S21: -4893846 | T21: -7018362 | U21: -24071682 | V21: =Input_IS!V15 -> -6580620
A22: Profit before income tax | B22: =SUM(B15,B17:B21) -> -1853445 | C22: =SUM(C15,C17:C21) -> -24281547 | D22: =SUM(D15,D17:D21) -> 54608570 | E22: =SUM(E15,E18:E21) -> 94374887 | F22: =SUM(F15,F17:F21) -> 67980289 | G22: =SUM(G15,G17:G21) -> 78394131 | H22: =SUM(H15,H17:H21) -> 71738209 | I22: =SUM(I15,I17:I21) -> 350622487 | J22: =SUM(J15,J17:J21) -> 196660047 | K22: =SUM(K15,K17:K21) -> 131878123 | L22: =SUM(L15,L17:L21) -> 135754132 | M22: =SUM(M15,M18:M21) -> 597813157 | N22: =SUM(N15,N17:N21) -> 200652999 | O22: =SUM(O15,O17:O21) -> 116962477 | P22: =SUM(P15,P17:P21) -> 219283276 | Q22: =SUM(Q15,Q17:Q21) -> 660697798 | R22: =SUM(R15,R17:R21) -> 17378194 | S22: =SUM(S15,S17:S21) -> 9306936 | T22: =SUM(T15,T17:T21) -> 135480676 | U22: =SUM(U15,U17:U21) -> 226200992 | V22: =SUM(V15,V17:V21) -> 96098649
A23: Income tax expense | B23: 0 | C23: -4835093 | D23: -2139775 | E23: -21949146 | F23: -17606663 | G23: -17666505 | H23: -20156072 | I23: -84920322 | J23: -45303646 | K23: -31049000 | L23: -33644503 | M23: -143374566 | N23: -47350203 | O23: -29202873 | P23: -52768558 | Q23: -159518137 | R23: -6785470 | S23: -5233881 | T23: -34672584 | U23: -64934163 | V23: =Input_IS!V16 -> -27753036
A24: Profit after income taxes | B24: =B22+B23 -> -1853445 | C24: =C22+C23 -> -29116640 | D24: =D22+D23 -> 52468795 | E24: =SUM(E22:E23) -> 72425741 | F24: =SUM(F22:F23) -> 50373626 | G24: =SUM(G22:G23) -> 60727626 | H24: =SUM(H22:H23) -> 51582137 | I24: =SUM(I22:I23) -> 265702165 | J24: =SUM(J22:J23) -> 151356401 | K24: =SUM(K22:K23) -> 100829123 | L24: =SUM(L22:L23) -> 102109629 | ... V24: =SUM(V22:V23) -> 68345613
A25: Net margin % | B25: =IFERROR(B24/B2,0) -> -0.0028642991 | C25: =IFERROR(C24/C2,0) -> -0.043463141 | D25: =IFERROR(D24/D2,0) -> 0.054878445 | E25: =E24/E2 -> 0.021552008 | F25: =IFERROR(F24/F2,0) -> 0.044908892 | G25: =IFERROR(G24/G2,0) -> 0.052718525 | H25: =IFERROR(H24/H2,0) -> 0.039113381 | I25: 0.087107885 | J25: =IFERROR(J24/J2,0) -> 0.086619911 | K25: =IFERROR(K24/K2,0) -> 0.064082695 | L25: =IFERROR(L24/L2,0) -> 0.051025254 | M25: =IFERROR(M24/M2,0) -> 0.060555883 | N25: =IFERROR(N24/N2,0) -> 0.067174166 | O25: =IFERROR(O24/O2,0) -> 0.042511058 | P25: =IFERROR(P24/P2,0) -> 0.065456681 | Q25: =IFERROR(Q24/Q2,0) -> 0.054322684 | ... V25: =IFERROR(V24/V2,0) -> 0.026707569
A26: Profit attributable to parent | B26: =B24-B27 -> -5287932 | C26: =C24-C27 -> -58233620 | D26: =D24-D27 -> 104937006 | E26: 93922932 | F26: =F24-F27 -> 100747232 | G26: =G24-G27 -> 10354020 | H26: =H24-H27 -> 51582137 | I26: 428385246 | J26: =J24-J27 -> 0 | K26: =K24-K27 -> 504371174 | L26: =L24-L27 -> -150076021 | M26: 454438562 | N26: =N24-N27 -> 153302796 | O26: =O24-O27 -> 87759603 | P26: =P24-P27 -> 166514713 | Q26: 501179645 | R26: =R24-R27 -> 10592722 | S26: =S24-S27 -> 4073046 | T26: =T24-T27 -> 100808076 | U26: 161266829 | V26: =V24-V27 -> 68345613
A27: Non-controlling interest | B27: =Input_IS!B18 -> 3434487 | C27: =Input_IS!C18 -> 29116980 | D27: =Input_IS!D18 -> -52468211 | E27: 1519 | F27: =Input_IS!F18 -> -50373606 | G27: =Input_IS!G18 -> 50373606 | H27: =Input_IS!H18 -> 0 | I27: 308 | J27: =Input_IS!J18 -> 151356401 | K27: =Input_IS!K18 -> -403542051 | L27: =Input_IS!L18 -> 252185650 | M27: 29 | N27: =Input_IS!N18 -> 0 | O27: =Input_IS!O18 -> 1 | P27: =Input_IS!P18 -> 5 | R27: =Input_IS!R18 -> 2 | S27: =Input_IS!S18 -> 9 | T27: =Input_IS!T18 -> 16 | V27: =Input_IS!V18 -> 0
A28: Earnings per share | B28: =Input_IS!B19 -> 0 | C28: =Input_IS!C19 -> 0 | D28: =Input_IS!D19 -> 0 | E28: 0.209 | F28: =Input_IS!F19 -> 0 | G28: =Input_IS!G19 -> 0 | H28: =Input_IS!H19 -> 0 | I28: 0.76 | J28: =Input_IS!J19 -> 0 | K28: =Input_IS!K19 -> 0 | L28: =Input_IS!L19 -> 0 | M28: 1.3 | N28: =Input_IS!N19 -> 0.44 | O28: =Input_IS!O19 -> 0.25 | P28: =Input_IS!P19 -> 0.48 | Q28: 1.44 | R28: =Input_IS!R19 -> 0.03 | S28: =Input_IS!S19 -> 0.013 | T28: =Input_IS!T19 -> 0.287 | U28: 0.46 | V28: =Input_IS!V19 -> 0.2

Sheet Balance Sheet
A1: Domty — Statement of Financial Position by Quarter-End (EGP) | B1: 1Q21 | C1: 2Q21 | D1: 3Q21 | E1: 4Q21 | F1: 1Q22 | G1: 2Q22 | H1: 3Q22 | I1: 4Q22 | J1: 1Q23 | K1: 2Q23 | L1: 3Q23 | M1: 4Q23 | N1: 1Q24 | O1: 2Q24 | P1: 3Q24 | Q1: 4Q24 | R1: 1Q25 | S1: 2Q25 | T1: 3Q25 | U1: 4Q25 | V1: 1Q26
A2: Assets
A3: Non-current assets
A4: Property, plant and equipment | B4: =Input_BS!B2 -> 580716667 | C4: =Input_BS!C2 -> 680979431 | D4: =Input_BS!D2 -> 742771604 | E4: =Input_BS!E2 -> 730770964 | F4: =Input_BS!F2 -> 709089656 | G4: =Input_BS!G2 -> 686911526 | H4: =Input_BS!H2 -> 702438044 | I4: =Input_BS!I2 -> 693270370 | ... V4: =Input_BS!V2 -> 775409439
A5: Projects under construction | B5: =Input_BS!B3 -> 194092151 | C5: =Input_BS!C3 -> 109649645 | D5: =Input_BS!D3 -> 28446645 | E5: =Input_BS!E3 -> 2487907 | F5: =Input_BS!F3 -> 56001562 | G5: =Input_BS!G3 -> 61003069 | H5: =Input_BS!H3 -> 51373180 | I5: =Input_BS!I3 -> 102537315 | ... V5: =Input_BS!V3 -> 90000322
A6: Investments in associate | B6: =Input_BS!B4 -> 0 | C6: =Input_BS!C4 -> 0 | D6: =Input_BS!D4 -> 0 | E6: =Input_BS!E4 -> 0 | F6: =Input_BS!F4 -> 0 | G6: =Input_BS!G4 -> 0 | H6: =Input_BS!H4 -> 0 | I6: =Input_BS!I4 -> 0 | ... V6: =Input_BS!V4 -> 0
A7: Investment in subsidiary | B7: =Input_BS!B5 -> 0 | C7: =Input_BS!C5 -> 0 | D7: =Input_BS!D5 -> 0 | E7: =Input_BS!E5 -> 0 | F7: =Input_BS!F5 -> 0 | G7: =Input_BS!G5 -> 0 | H7: =Input_BS!H5 -> 0 | I7: =Input_BS!I5 -> 0 | ... V7: =Input_BS!V5 -> 72502733
A8: Other non-current assets / balancing | B8: =Input_BS!B6 -> 0 | C8: =Input_BS!C6 -> 0 | D8: =Input_BS!D6 -> 4629853 | E8: =Input_BS!E6 -> 54629853 | F8: =Input_BS!F6 -> 4629853 | G8: =Input_BS!G6 -> 4629853 | H8: =Input_BS!H6 -> -753811224 | I8: =Input_BS!I6 -> 4018553 | J8: 4018553 | K8: =Input_BS!K6 -> 4155415 | L8: =Input_BS!L6 -> 4155415 | M8: =Input_BS!M6 -> 0 | N8: =Input_BS!N6 -> 0 | O8: =Input_BS!O6 -> -974999020 | P8: =Input_BS!P6 -> 0 | Q8: =Input_BS!Q6 -> 0 | R8: =Input_BS!R6 -> 0 | ... V8: =Input_BS!V6 -> 0
A9: Total non-current assets | B9: =SUM(B4:B8) -> 774808818 | C9: =SUM(C4:C8) -> 790629076 | D9: =SUM(D4:D8) -> 775848102 | E9: =SUM(E4:E8) -> 787888724 | F9: =SUM(F4:F8) -> 769721071 | G9: =SUM(G4:G8) -> 752544448 | H9: =SUM(H4:H8) -> 0 | I9: =SUM(I4:I8) -> 799826238 | ... V9: =SUM(V4:V8) -> 937912494
A10: Current assets
A11: Inventories | B11: =Input_BS!B7 -> 357787229 | C11: =Input_BS!C7 -> 439773442 | D11: =Input_BS!D7 -> 494319945 | E11: =Input_BS!E7 -> 14255299 | F11: =Input_BS!F7 -> 15842107 | G11: =Input_BS!G7 -> 716197484 | H11: =Input_BS!H7 -> 0 | I11: =Input_BS!I7 -> 572087082 | ... V11: =Input_BS!V7 -> 1194680642
A12: Accounts and notes receivable | B12: =Input_BS!B8 -> 610803432 | C12: =Input_BS!C8 -> 576907582 | D12: =Input_BS!D8 -> 669512956 | E12: =Input_BS!E8 -> 637237807 | F12: =Input_BS!F8 -> 686879995 | G12: =Input_BS!G8 -> 779953345 | H12: =Input_BS!H8 -> 0 | I12: =Input_BS!I8 -> 591657820 | ... V12: =Input_BS!V8 -> 1800636217
A13: Prepayments and other debit balances / balancing | B13: =Input_BS!B9 -> 495455767 | C13: =Input_BS!C9 -> 505746612 | D13: =Input_BS!D9 -> 518535034 | E13: =Input_BS!E9 -> 957804744 | F13: =Input_BS!F9 -> 1005759600 | G13: =Input_BS!G9 -> 510256601 | H13: =Input_BS!H9 -> -264146556 | I13: =Input_BS!I9 -> 695386168 | ... V13: =Input_BS!V9 -> 691837974
A14: Financial investment at amortized cost - Treasury bills | B14: =Input_BS!B10 -> 0 | C14: =Input_BS!C10 -> 0 | D14: =Input_BS!D10 -> 0 | E14: =Input_BS!E10 -> 0 | F14: =Input_BS!F10 -> 0 | G14: =Input_BS!G10 -> 0 | H14: =Input_BS!H10 -> 0 | I14: =Input_BS!I10 -> 0 | ... V14: =Input_BS!V10 -> 0
A15: Cash on hand and at banks | B15: =Input_BS!B11 -> 125038404 | C15: =Input_BS!C11 -> 128075432 | D15: =Input_BS!D11 -> 132770425 | E15: =Input_BS!E11 -> 163942106 | F15: =Input_BS!F11 -> 177666199 | G15: =Input_BS!G11 -> 205680242 | H15: =Input_BS!H11 -> 264146556 | I15: =Input_BS!I11 -> 440158488 | ... V15: =Input_BS!V11 -> 319665548
A16: Total current assets | B16: =SUM(B11:B15) -> 1589084832 | C16: =SUM(C11:C15) -> 1650503068 | D16: =SUM(D11:D15) -> 1815138360 | E16: =SUM(E11:E15) -> 1773239956 | F16: =SUM(F11:F15) -> 1886147901 | G16: =SUM(G11:G15) -> 2212087672 | H16: =SUM(H11:H15) -> 0 | I16: =SUM(I11:I15) -> 2299289558 | ... V16: =SUM(V11:V15) -> 4006820381
A17: Total assets | B17: =B9+B16 -> 2363893650 | C17: =C9+C16 -> 2441132144 | D17: =D9+D16 -> 2590986462 | E17: =E9+E16 -> 2561128680 | F17: =F9+F16 -> 2655868972 | G17: =G9+G16 -> 2964632120 | H17: =H9+H16 -> 0 | I17: =I9+I16 -> 3099115796 | ... V17: =V9+V16 -> 4944732875
A18: Equity
A19: Issued and paid-up capital | B19: =Input_BS!B12 -> 56521739 | C19: =Input_BS!C12 -> 56521739 | D19: =Input_BS!D12 -> 56521739 | E19: =Input_BS!E12 -> 56521739 | F19: =Input_BS!F12 -> 56521739 | G19: =Input_BS!G12 -> 56521739 | H19: =Input_BS!H12 -> 56521739 | I19: =Input_BS!I12 -> 56521739 | ... V19: =Input_BS!V12 -> 56521739
A20: Legal reserve | B20: =Input_BS!B13 -> 28260870 | C20: =Input_BS!C13 -> 28260870 | D20: =Input_BS!D13 -> 28260870 | E20: =Input_BS!E13 -> 28260870 | F20: =Input_BS!F13 -> 28260870 | G20: =Input_BS!G13 -> 28260870 | H20: =Input_BS!H13 -> 28260870 | I20: =Input_BS!I13 -> 28260870 | ... V20: =Input_BS!V13 -> 28260870
A21: Special reserve / share premium | B21: =Input_BS!B14 -> 283422423 | C21: =Input_BS!C14 -> 283422423 | D21: =Input_BS!D14 -> 283422423 | E21: =Input_BS!E14 -> 283422423 | F21: =Input_BS!F14 -> 283422423 | G21: =Input_BS!G14 -> 283422423 | H21: =Input_BS!H14 -> 283422423 | I21: =Input_BS!I14 -> 283422423 | ... V21: =Input_BS!V14 -> 283422423
A22: Other reserves | B22: =Input_BS!B15 -> 170196 | C22: =Input_BS!C15 -> 170196 | D22: =Input_BS!D15 -> 170196 | E22: =Input_BS!E15 -> 170196 | F22: =Input_BS!F15 -> 170196 | G22: =Input_BS!G15 -> 170196 | H22: =Input_BS!H15 -> 170196 | I22: =Input_BS!I15 -> 170196 | ... V22: =Input_BS!V15 -> 170196
A23: Retained earnings and other equity reserves / balancing | B23: =Input_BS!B16 -> 437425924 | C23: =Input_BS!C16 -> 409775809 | D23: =Input_BS!D16 -> 460778079 | E23: =Input_BS!E16 -> 490330894 | F23: =Input_BS!F16 -> 540704520 | G23: =Input_BS!G16 -> 601432146 | H23: =Input_BS!H16 -> -368353839 | I23: =Input_BS!I16 -> 756033059 | ... V23: =Input_BS!V16 -> 1153512638
A24: Non-controlling interests | B24: =Input_BS!B17 -> 0 | C24: =Input_BS!C17 -> 0 | D24: =Input_BS!D17 -> 0 | E24: =Input_BS!E17 -> 0 | F24: =Input_BS!F17 -> 0 | G24: =Input_BS!G17 -> 0 | H24: =Input_BS!H17 -> 0 | I24: =Input_BS!I17 -> 0 | ... V24: =Input_BS!V17 -> 0
A25: Total equity | B25: =SUM(B19:B24) -> 805801152 | C25: =SUM(C19:C24) -> 778151037 | D25: =SUM(D19:D24) -> 829153307 | E25: =SUM(E19:E24) -> 858706122 | F25: =SUM(F19:F24) -> 909079748 | G25: =SUM(G19:G24) -> 969807374 | H25: =SUM(H19:H24) -> 21389 | I25: =SUM(I19:I24) -> 1124408287 | ... V25: =SUM(V19:V24) -> 1521887866
A26: Non-current liabilities
A27: Long-term loans | B27: =Input_BS!B18 -> 0 | C27: =Input_BS!C18 -> 0 | D27: =Input_BS!D18 -> 0 | E27: =Input_BS!E18 -> 0 | F27: =Input_BS!F18 -> 0 | G27: =Input_BS!G18 -> 0 | H27: =Input_BS!H18 -> 0 | I27: =Input_BS!I18 -> 0 | ... V27: =Input_BS!V18 -> 0
A28: Lease liability - long term | B28: =Input_BS!B19 -> 0 | C28: =Input_BS!C19 -> 0 | D28: =Input_BS!D19 -> 0 | E28: =Input_BS!E19 -> 0 | F28: =Input_BS!F19 -> 0 | G28: =Input_BS!G19 -> 0 | H28: =Input_BS!H19 -> 0 | I28: =Input_BS!I19 -> 0 | ... V28: =Input_BS!V19 -> 0
A29: Deferred tax liabilities | B29: =Input_BS!B20 -> 0 | C29: =Input_BS!C20 -> 0 | D29: =Input_BS!D20 -> 0 | E29: =Input_BS!E20 -> 0 | F29: =Input_BS!F20 -> 0 | G29: =Input_BS!G20 -> 0 | H29: =Input_BS!H20 -> 0 | I29: =Input_BS!I20 -> 0 | ... V29: =Input_BS!V20 -> 0
A30: Other non-current liabilities / balancing | B30: =Input_BS!B21 -> 190532794 | C30: =Input_BS!C21 -> 201172347 | D30: =Input_BS!D21 -> 191323203 | E30: =Input_BS!E21 -> 179897567 | F30: =Input_BS!F21 -> 197456281 | G30: =Input_BS!G21 -> 183908773 | H30: =Input_BS!H21 -> 0 | I30: =Input_BS!I21 -> 197298878 | ... V30: =Input_BS!V21 -> 159218525
A31: Total non-current liabilities | B31: =SUM(B27:B30) -> 190532794 | C31: =SUM(C27:C30) -> 201172347 | D31: =SUM(D27:D30) -> 191323203 | E31: =SUM(E27:E30) -> 179897567 | F31: =SUM(F27:F30) -> 197456281 | G31: =SUM(G27:G30) -> 183908773 | H31: =SUM(H27:H30) -> 0 | I31: =SUM(I27:I30) -> 197298878 | ... V31: =SUM(V27:V30) -> 159218525
A32: Current liabilities
A33: Credit facilities - short term | B33: =Input_BS!B22 -> 893781783 | C33: =Input_BS!C22 -> 1079329424 | D33: =Input_BS!D22 -> 1143833077 | E33: =Input_BS!E22 -> 1009448556 | F33: =Input_BS!F22 -> 1018839703 | G33: =Input_BS!G22 -> 1263765727 | H33: =Input_BS!H22 -> 1269605117 | I33: =Input_BS!I22 -> 1247679118 | ... V33: =Input_BS!V22 -> 2121862769
A34: Short-term loans | B34: =Input_BS!B23 -> 0 | C34: =Input_BS!C23 -> 0 | D34: =Input_BS!D23 -> 0 | E34: =Input_BS!E23 -> 0 | F34: =Input_BS!F23 -> 0 | G34: =Input_BS!G23 -> 0 | H34: =Input_BS!H23 -> 0 | I34: =Input_BS!I23 -> 0 | ... V34: =Input_BS!V23 -> 25295743
A35: Lease liability - short term | B35: =Input_BS!B24 -> 0 | C35: =Input_BS!C24 -> 0 | D35: =Input_BS!D24 -> 0 | E35: =Input_BS!E24 -> 0 | F35: =Input_BS!F24 -> 0 | G35: =Input_BS!G24 -> 0 | H35: =Input_BS!H24 -> 0 | I35: =Input_BS!I24 -> 0 | ... V35: =Input_BS!V24 -> 0
A36: Trade and notes payable | B36: =Input_BS!B25 -> 230707379 | C36: =Input_BS!C25 -> 251076605 | D36: =Input_BS!D25 -> 277948477 | E36: =Input_BS!E25 -> 362791272 | F36: =Input_BS!F25 -> 324673498 | G36: =Input_BS!G25 -> 333838339 | H36: =Input_BS!H25 -> 312942677 | I36: =Input_BS!I25 -> 229886487 | ... V36: =Input_BS!V25 -> 711930677
A37: Provisions | B37: =Input_BS!B26 -> 0 | C37: =Input_BS!C26 -> 0 | D37: =Input_BS!D26 -> 0 | E37: =Input_BS!E26 -> 0 | F37: =Input_BS!F26 -> 0 | G37: =Input_BS!G26 -> 0 | H37: =Input_BS!H26 -> 0 | I37: =Input_BS!I26 -> 0 | ... V37: =Input_BS!V26 -> 0
A38: Accrued expenses and other credit balances | B38: =Input_BS!B27 -> 0 | C38: =Input_BS!C27 -> 0 | D38: =Input_BS!D27 -> 0 | E38: =Input_BS!E27 -> 0 | F38: =Input_BS!F27 -> 0 | G38: =Input_BS!G27 -> 0 | H38: =Input_BS!H27 -> 0 | I38: =Input_BS!I27 -> 0 | ... V38: =Input_BS!V27 -> 0
A39: Income tax payable | B39: =Input_BS!B28 -> 0 | C39: =Input_BS!C28 -> 0 | D39: =Input_BS!D28 -> 0 | E39: =Input_BS!E28 -> 0 | F39: =Input_BS!F28 -> 0 | G39: =Input_BS!G28 -> 0 | H39: =Input_BS!H28 -> 0 | I39: =Input_BS!I28 -> 0 | ... V39: =Input_BS!V28 -> 0
A40: Other current liabilities / balancing | B40: =B17-B25-B31-SUM(B33:B39) -> 243070542 | C40: =C17-C25-C31-SUM(C33:C39) -> 131402731 | D40: =D17-D25-D31-SUM(D33:D39) -> 148728398 | E40: =E17-E25-E31-SUM(E33:E39) -> 150285163 | F40: =F17-F25-F31-SUM(F33:F39) -> 205819742 | G40: =G17-G25-G31-SUM(G33:G39) -> 213311907 | H40: =H17-H25-H31-SUM(H33:H39) -> -1582569183 | I40: =I17-I25-I31-SUM(I33:I39) -> 299843026 | ... V40: =V17-V25-V31-SUM(V33:V39) -> 404537295
...

Sheet Cash Flow
A1: Domty — Quarterly Statement of Cash Flows (EGP) | B1: 1Q21 | C1: 2Q21 | D1: 3Q21 | E1: 4Q21 | F1: 1Q22 | G1: 2Q22 | H1: 3Q22 | I1: 4Q22 | J1: 1Q23 | K1: 2Q23 | L1: 3Q23 | M1: 4Q23 | N1: 1Q24 | O1: 2Q24 | P1: 3Q24 | Q1: 4Q24 | R1: 1Q25 | S1: 2Q25 | T1: 3Q25 | U1: 4Q25 | V1: 1Q26
A3: Net cash flows from operating activities | B3: =Input_CF!B2 -> 20580943 | C3: =Input_CF!C2 -> 3037028 | D3: =Input_CF!D2 -> 4694993 | E3: =Input_CF!E2 -> 31171681 | F3: =Input_CF!F2 -> 1593999 | G3: =Input_CF!G2 -> -219712930 | H3: =Input_CF!H2 -> 217910417 | I3: =Input_CF!I2 -> 272760010 | ... V3: =Input_CF!V2 -> -299256755 | W3: Source statement line / reconstructed if OCR missing
A4: Net cash flows from investing activities | B4: =Input_CF!B3 -> 0 | C4: =Input_CF!C3 -> 0 | D4: =Input_CF!D3 -> 0 | E4: =Input_CF!E3 -> 0 | F4: =Input_CF!F3 -> -4731973 | G4: =Input_CF!G3 -> 5702332 | H4: =Input_CF!H3 -> 41475844 | I4: =Input_CF!I3 -> -291785165 | ... V4: =Input_CF!V3 -> 0 | W4: Source statement line / reconstructed if OCR missing
A5: Net cash flows from financing activities | B5: =Input_CF!B4 -> 0 | C5: =Input_CF!C4 -> 0 | D5: =Input_CF!D4 -> 0 | E5: =Input_CF!E4 -> 0 | F5: =Input_CF!F4 -> 23914398 | G5: =Input_CF!G4 -> 229972310 | H5: =Input_CF!H4 -> 13086482 | I5: =Input_CF!I4 -> -13969342 | ... V5: =Input_CF!V4 -> 0 | W5: Source statement line / reconstructed if OCR missing
A6: Foreign exchange / residual effect | B6: =Input_CF!B5 -> 0 | C6: =Input_CF!C5 -> 0 | D6: =Input_CF!D5 -> 0 | E6: =Input_CF!E5 -> 0 | F6: =Input_CF!F5 -> -7052331 | G6: =Input_CF!G5 -> 12052331 | H6: =Input_CF!H5 -> -214006429 | I6: =Input_CF!I5 -> 209006429 | ... V6: =Input_CF!V5 -> 0 | W6: Balancing FX/residual line
A7: Cash and cash equivalents - beginning | B7: =Input_CF!B6 -> 104457461 | C7: =Input_CF!C6 -> 125038404 | D7: =Input_CF!D6 -> 128075432 | E7: =Input_CF!E6 -> 132770425 | F7: =Input_CF!F6 -> 163942106 | G7: =Input_CF!G6 -> 177666199 | H7: =Input_CF!H6 -> 205680242 | I7: =Input_CF!I6 -> 264146556 | ... V7: =Input_CF!V6 -> 618922303 | W7: Prior FY cash balance
A8: Net change in cash | B8: =SUM(B3:B6) -> 20580943 | C8: =SUM(C3:C6) -> 3037028 | D8: =SUM(D3:D6) -> 4694993 | E8: =SUM(E3:E6) -> 31171681 | F8: =SUM(F3:F6) -> 13724093 | G8: =SUM(G3:G6) -> 28014043 | H8: =SUM(H3:H6) -> 58466314 | I8: =SUM(I3:I6) -> 176011932 | ... V8: =SUM(V3:V6) -> -299256755 | W8: CFO + CFI + CFF
A9: Cash and cash equivalents - end (computed) | B9: =B7+B8 -> 125038404 | C9: =C7+C8 -> 128075432 | D9: =D7+D8 -> 132770425 | E9: =E7+E8 -> 163942106 | F9: =F7+F8 -> 177666199 | G9: =G7+G8 -> 205680242 | H9: =H7+H8 -> 264146556 | I9: =I7+I8 -> 440158488 | ... V9: =V7+V8 -> 319665548 | W9: Beginning cash + net change + FX/residual
A10: Cash and cash equivalents - end (source) | B10: =Input_CF!B7 -> 125038404 | C10: =Input_CF!C7 -> 128075432 | D10: =Input_CF!D7 -> 132770425 | E10: =Input_CF!E7 -> 163942106 | F10: =Input_CF!F7 -> 177666199 | G10: =Input_CF!G7 -> 205680242 | H10: =Input_CF!H7 -> 264146556 | I10: =Input_CF!I7 -> 440158488 | ... V10: =Input_CF!V7 -> 319665548 | W10: Source statement / balance sheet cash
A11: Cash check | B11: =B9-B10 -> 0 | C11: =C9-C10 -> 0 | D11: =D9-D10 -> 0 | E11: =E9-E10 -> 0 | F11: =F9-F10 -> 0 | G11: =G9-G10 -> 0 | H11: =H9-H10 -> 0 | I11: =I9-I10 -> 0 | ... V11: =V9-V10 -> 0 | W11: Computed cash end - source cash end

Sheet Ratios
A1: Domty — Financial Ratios (Quarterly + FY)
A2: Metric | B2: ='Income Statement'!B1 -> 1Q21 | C2: ='Income Statement'!C1 -> 2Q21 | D2: ='Income Statement'!D1 -> 3Q21 | E2: ='Income Statement'!E1 -> FY21 | F2: ='Income Statement'!F1 -> 1Q22 | G2: ='Income Statement'!G1 -> 2Q22 | H2: ='Income Statement'!H1 -> 3Q22 | I2: ='Income Statement'!I1 -> FY22 | ... V2: ='Income Statement'!V1 -> 1Q26
A3: Period days | B3: 90 | C3: 90 | D3: 90 | E3: 365 | F3: 90 | G3: 90 | H3: 90 | I3: 365 | J3: 90 | K3: 90 | L3: 90 | M3: 365 | N3: 90 | O3: 90 | P3: 90 | Q3: 365 | R3: 90 | S3: 90 | T3: 90 | U3: 365 | V3: 90
A5: PROFITABILITY
A6: Gross margin | B6: =IFERROR('Income Statement'!B4/'Income Statement'!B2,0) -> 0.20509387 | C6: =IFERROR('Income Statement'!C4/'Income Statement'!C2,0) -> 0.2092308 | D6: =IFERROR('Income Statement'!D4/'Income Statement'!D2,0) -> 0.23305666 | E6: =IFERROR('Income Statement'!E4/'Income Statement'!E2,0) -> 0.22409679 | F6: =IFERROR('Income Statement'!F4/'Income Statement'!F2,0) -> 0.24018593 | G6: =IFERROR('Income Statement'!G4/'Income Statement'!G2,0) -> 0.24636001 | H6: =IFERROR('Income Statement'!H4/'Income Statement'!H2,0) -> 0.22826233 | I6: =IFERROR('Income Statement'!I4/'Income Statement'!I2,0) -> 0.24363249 | ... V6: =IFERROR('Income Statement'!V4/'Income Statement'!V2,0) -> 0.24374674
A7: Operating margin (EBIT) | B7: =IFERROR('Income Statement'!B15/'Income Statement'!B2,0) -> 0.014653233 | C7: =IFERROR('Income Statement'!C15/'Income Statement'!C2,0) -> -0.0092940756 | D7: =IFERROR('Income Statement'!D15/'Income Statement'!D2,0) -> 0.077960476 | E7: =IFERROR('Income Statement'!E15/'Income Statement'!E2,0) -> 0.048459408 | F7: =IFERROR('Income Statement'!F15/'Income Statement'!F2,0) -> 0.087825969 | G7: =IFERROR('Income Statement'!G15/'Income Statement'!G2,0) -> 0.088805184 | H7: =IFERROR('Income Statement'!H15/'Income Statement'!H2,0) -> 0.074170631 | I7: =IFERROR('Income Statement'!I15/'Income Statement'!I2,0) -> 0.088899038 | ... V7: =IFERROR('Income Statement'!V15/'Income Statement'!V2,0) -> 0.091459273
A8: Net margin | B8: =IFERROR('Income Statement'!B24/'Income Statement'!B2,0) -> -0.0028642991 | C8: =IFERROR('Income Statement'!C24/'Income Statement'!C2,0) -> -0.043463141 | D8: =IFERROR('Income Statement'!D24/'Income Statement'!D2,0) -> 0.054878445 | E8: =IFERROR('Income Statement'!E24/'Income Statement'!E2,0) -> 0.021552008 | F8: =IFERROR('Income Statement'!F24/'Income Statement'!F2,0) -> 0.044908892 | G8: =IFERROR('Income Statement'!G24/'Income Statement'!G2,0) -> 0.052718525 | H8: =IFERROR('Income Statement'!H24/'Income Statement'!H2,0) -> 0.039113381 | I8: =IFERROR('Income Statement'!I24/'Income Statement'!I2,0) -> 0.050921543 | ... V8: =IFERROR('Income Statement'!V24/'Income Statement'!V2,0) -> 0.026707569
A9: Return on Assets (ROA) | B9: =IFERROR('Income Statement'!B24/'Balance Sheet'!B17,0) -> -0.00078406446 | C9: =IFERROR('Income Statement'!C24/'Balance Sheet'!C17,0) -> -0.011927515 | D9: =IFERROR('Income Statement'!D24/'Balance Sheet'!D17,0) -> 0.020250509 | E9: =IFERROR('Income Statement'!E24/'Balance Sheet'!E17,0) -> 0.028278837 | F9: =IFERROR('Income Statement'!F24/'Balance Sheet'!F17,0) -> 0.018966909 | G9: =IFERROR('Income Statement'!G24/'Balance Sheet'!G17,0) -> 0.020484034 | H9: =IFERROR('Income Statement'!H24/'Balance Sheet'!H17,0) -> 0 | I9: =IFERROR('Income Statement'!I24/'Balance Sheet'!I17,0) -> 0.08573483 | ... V9: =IFERROR('Income Statement'!V24/'Balance Sheet'!V17,0) -> 0.013821902
A10: Return on Equity (ROE) | B10: =IFERROR('Income Statement'!B24/'Balance Sheet'!B25,0) -> -0.002300127 | C10: =IFERROR('Income Statement'!C24/'Balance Sheet'!C25,0) -> -0.037417723 | D10: =IFERROR('Income Statement'!D24/'Balance Sheet'!D25,0) -> 0.063279968 | E10: =IFERROR('Income Statement'!E24/'Balance Sheet'!E25,0) -> 0.084342873 | F10: =IFERROR('Income Statement'!F24/'Balance Sheet'!F25,0) -> 0.055411669 | G10: =IFERROR('Income Statement'!G24/'Balance Sheet'!G25,0) -> 0.062618235 | H10: =IFERROR('Income Statement'!H24/'Balance Sheet'!H25,0) -> 2411.6199 | I10: =IFERROR('Income Statement'!I24/'Balance Sheet'!I25,0) -> 0.23630399 | ... V10: =IFERROR('Income Statement'!V24/'Balance Sheet'!V25,0) -> 0.044908442
A11: Return on Invested Capital (ROIC, assumed 22.5% tax) | B11: =IFERROR('Income Statement'!B15*(1-0.225)/('Balance Sheet'!B25+'Balance Sheet'!B27+'Balance Sheet'!B33+'Balance Sheet'!B34),0) -> 0.0043236857 | C11: =IFERROR('Income Statement'!C15*(1-0.225)/('Balance Sheet'!C25+'Balance Sheet'!C27+'Balance Sheet'!C33+'Balance Sheet'!C34),0) -> -0.0025977885 | D11: =IFERROR('Income Statement'!D15*(1-0.225)/('Balance Sheet'!D25+'Balance Sheet'!D27+'Balance Sheet'!D33+'Balance Sheet'!D34),0) -> 0.029278673 | E11: =IFERROR('Income Statement'!E15*(1-0.225)/('Balance Sheet'!E25+'Balance Sheet'!E27+'Balance Sheet'!E33+'Balance Sheet'!E34),0) -> 0.067557283 | F11: =IFERROR('Income Statement'!F15*(1-0.225)/('Balance Sheet'!F25+'Balance Sheet'!F27+'Balance Sheet'!F33+'Balance Sheet'!F34),0) -> 0.039601045 | G11: =IFERROR('Income Statement'!G15*(1-0.225)/('Balance Sheet'!G25+'Balance Sheet'!G27+'Balance Sheet'!G33+'Balance Sheet'!G34),0) -> 0.03549465 | H11: =IFERROR('Income Statement'!H15*(1-0.225)/('Balance Sheet'!H25+'Balance Sheet'!H27+'Balance Sheet'!H33+'Balance Sheet'!H34),0) -> 0.059707882 | I11: =IFERROR('Income Statement'!I15*(1-0.225)/('Balance Sheet'!I25+'Balance Sheet'!I27+'Balance Sheet'!I33+'Balance Sheet'!I34),0) -> 0.15155198 | ... V11: =IFERROR('Income Statement'!V15*(1-0.225)/('Balance Sheet'!V25+'Balance Sheet'!V27+'Balance Sheet'!V33+'Balance Sheet'!V34),0) -> 0.049437048
A13: LIQUIDITY
A14: Current ratio | B14: =IFERROR('Balance Sheet'!B16/'Balance Sheet'!B41,0) -> 1.1619857 | C14: =IFERROR('Balance Sheet'!C16/'Balance Sheet'!C41,0) -> 1.1290828 | D14: =IFERROR('Balance Sheet'!D16/'Balance Sheet'!D41,0) -> 1.1557637 | E14: =IFERROR('Balance Sheet'!E16/'Balance Sheet'!E41,0) -> 1.1646705 | F14: =IFERROR('Balance Sheet'!F16/'Balance Sheet'!F41,0) -> 1.2173935 | G14: =IFERROR('Balance Sheet'!G16/'Balance Sheet'!G41,0) -> 1.2215297 | H14: =IFERROR('Balance Sheet'!H16/'Balance Sheet'!H41,0) -> 0 | I14: =IFERROR('Balance Sheet'!I16/'Balance Sheet'!I41,0) -> 1.293619 | ... V14: =IFERROR('Balance Sheet'!V16/'Balance Sheet'!V41,0) -> 1.2277203
A15: Quick ratio | B15: =IFERROR(('Balance Sheet'!B16-'Balance Sheet'!B11)/'Balance Sheet'!B41,0) -> 0.90036113 | C15: =IFERROR(('Balance Sheet'!C16-'Balance Sheet'!C11)/'Balance Sheet'!C41,0) -> 0.82824078 | D15: =IFERROR(('Balance Sheet'!D16-'Balance Sheet'!D11)/'Balance Sheet'!D41,0) -> 0.84101245 | E15: =IFERROR(('Balance Sheet'!E16-'Balance Sheet'!E11)/'Balance Sheet'!E41,0) -> 1.1553076 | F15: =IFERROR(('Balance Sheet'!F16-'Balance Sheet'!F11)/'Balance Sheet'!F41,0) -> 1.2071684 | G15: =IFERROR(('Balance Sheet'!G16-'Balance Sheet'!G11)/'Balance Sheet'!G41,0) -> 0.82604064 | H15: =IFERROR(('Balance Sheet'!H16-'Balance Sheet'!H11)/'Balance Sheet'!H41,0) -> 0 | I15: =IFERROR(('Balance Sheet'!I16-'Balance Sheet'!I11)/'Balance Sheet'!I41,0) -> 0.97175317 | ... V15: =IFERROR(('Balance Sheet'!V16-'Balance Sheet'!V11)/'Balance Sheet'!V41,0) -> 0.86166102
